Workbook

Sheet Updation Date
A12: Region | B12: Updated On DATE
A13: DELHI | B13: 45484
A14: MUMBAI | B14: 45468
A15: KOLKATTA
A16: CHENNAI | B16: 45814
A17: BANGALORE | B17: 44866
A18: HYDERABAD
AO139: received

Sheet Total summary
A1: Shed | B1: ='Bangalore Summary'!B3 -> Total Panel | C1: ='Bangalore Summary'!C3 -> Software version in Conv | D1: ='Bangalore Summary'!D3 -> Count of Software version of display | E1: ='Bangalore Summary'!E3 -> Removal of metal short link from M9000 with wire | F1: ='Bangalore Summary'!F3 -> Replacement of 10 amp fuse with 20 amp | G1: ='Bangalore Summary'!G3 -> Shifting of wires on O/P contactor | H1: ='Bangalore Summary'!H3 -> External earth fault wire | I1: ='Bangalore Summary'!I3 -> Shifting of wire of output voltage available lamp | ... U1: ='Bangalore Summary'!U3 -> Count of Steel mesh on cyclonic filter on looc wall | V1: Region
A2: ='Bangalore Summary'!A4 -> Krishnarajipuram | B2: ='Bangalore Summary'!B4 -> 72 | C2: ='Bangalore Summary'!C4 -> 32 | D2: ='Bangalore Summary'!D4 -> 60 | E2: ='Bangalore Summary'!E4 -> 72 | F2: ='Bangalore Summary'!F4 -> 72 | G2: ='Bangalore Summary'!G4 -> 72 | H2: ='Bangalore Summary'!H4 -> 72 | ... U2: ='Bangalore Summary'!U4 -> 46 | V2: BAN
A3: ='Chennai Summary'!A4 -> Erode | B3: ='Chennai Summary'!B4 -> 100 | C3: ='Chennai Summary'!C4 -> 96 | D3: ='Chennai Summary'!D4 -> 98 | E3: ='Chennai Summary'!E4 -> 70 | F3: ='Chennai Summary'!F4 -> 98 | G3: ='Chennai Summary'!G4 -> 54 | H3: ='Chennai Summary'!H4 -> 98 | ... U3: ='Chennai Summary'!U4 -> 84 | V3: CHE
A4: ='Chennai Summary'!A5 -> Raipuram | B4: ='Chennai Summary'!B5 -> 130 | C4: ='Chennai Summary'!C5 -> 100 | D4: ='Chennai Summary'!D5 -> 106 | E4: ='Chennai Summary'!E5 -> 93 | F4: ='Chennai Summary'!F5 -> 130 | G4: ='Chennai Summary'!G5 -> 68 | H4: ='Chennai Summary'!H5 -> 130 | ... U4: ='Chennai Summary'!U5 -> 102 | V4: CHE
A5: ='Hyderabad Summary'!A4 -> BZA | B5: ='Hyderabad Summary'!B4 -> 44 | C5: ='Hyderabad Summary'!C4 -> 17 | D5: ='Hyderabad Summary'!D4 -> 17 | E5: ='Hyderabad Summary'!E4 -> 32 | F5: ='Hyderabad Summary'!F4 -> 32 | G5: ='Hyderabad Summary'!G4 -> 0 | H5: ='Hyderabad Summary'!H4 -> 32 | ... U5: ='Hyderabad Summary'!U4 -> 32 | V5: HYD
A6: ='Hyderabad Summary'!A5 -> Lallaguda | B6: ='Hyderabad Summary'!B5 -> 128 | C6: ='Hyderabad Summary'!C5 -> 33 | D6: ='Hyderabad Summary'!D5 -> 33 | E6: ='Hyderabad Summary'!E5 -> 64 | F6: ='Hyderabad Summary'!F5 -> 64 | G6: ='Hyderabad Summary'!G5 -> 3 | H6: ='Hyderabad Summary'!H5 -> 64 | ... U6: ='Hyderabad Summary'!U5 -> 84 | V6: HYD
A7: ='Delhi Summary'!A4 -> BGKT | B7: ='Delhi Summary'!B4 -> 18 | C7: ='Delhi Summary'!C4 -> 2 | D7: ='Delhi Summary'!D4 -> 2 | E7: ='Delhi Summary'!E4 -> 0 | F7: ='Delhi Summary'!F4 -> 14 | G7: ='Delhi Summary'!G4 -> 16 | H7: ='Delhi Summary'!H4 -> 10 | ... U7: ='Delhi Summary'!U4 -> 2 | V7: DEL
A8: ='Delhi Summary'!A5 -> ELS GKP | B8: ='Delhi Summary'!B5 -> 12 | C8: ='Delhi Summary'!C5 -> 8 | D8: ='Delhi Summary'!D5 -> 10 | E8: ='Delhi Summary'!E5 -> 10 | F8: ='Delhi Summary'!F5 -> 12 | G8: ='Delhi Summary'!G5 -> 2 | H8: ='Delhi Summary'!H5 -> 10 | ... U8: ='Delhi Summary'!U5 -> 12 | V8: DEL
A9: ='Delhi Summary'!A6 -> Gaziabad | B9: ='Delhi Summary'!B6 -> 103 | C9: ='Delhi Summary'!C6 -> 77 | D9: ='Delhi Summary'!D6 -> 77 | E9: ='Delhi Summary'!E6 -> 48 | F9: ='Delhi Summary'!F6 -> 92 | G9: ='Delhi Summary'!G6 -> 77 | H9: ='Delhi Summary'!H6 -> 79 | ... U9: ='Delhi Summary'!U6 -> 88 | V9: DEL
A10: ='Delhi Summary'!A7 -> Ghaziabad | B10: ='Delhi Summary'!B7 -> 2 | C10: ='Delhi Summary'!C7 -> 0 | D10: ='Delhi Summary'!D7 -> 0 | E10: ='Delhi Summary'!E7 -> 2 | F10: ='Delhi Summary'!F7 -> 2 | G10: ='Delhi Summary'!G7 -> 2 | H10: ='Delhi Summary'!H7 -> 2 | ... U10: ='Delhi Summary'!U7 -> 2 | V10: DEL
A11: ='Delhi Summary'!A8 -> Gonda | B11: ='Delhi Summary'!B8 -> 18 | C11: ='Delhi Summary'!C8 -> 4 | D11: ='Delhi Summary'!D8 -> 6 | E11: ='Delhi Summary'!E8 -> 6 | F11: ='Delhi Summary'!F8 -> 18 | G11: ='Delhi Summary'!G8 -> 0 | H11: ='Delhi Summary'!H8 -> 16 | ... U11: ='Delhi Summary'!U8 -> 18 | V11: DEL
A12: ='Delhi Summary'!A9 -> Kanpur | B12: ='Delhi Summary'!B9 -> 78 | C12: ='Delhi Summary'!C9 -> 62 | D12: ='Delhi Summary'!D9 -> 56 | E12: ='Delhi Summary'!E9 -> 29 | F12: ='Delhi Summary'!F9 -> 78 | G12: ='Delhi Summary'!G9 -> 78 | H12: ='Delhi Summary'!H9 -> 78 | ... U12: ='Delhi Summary'!U9 -> 78 | V12: DEL
A13: ='Delhi Summary'!A10 -> LUDHIANA | B13: ='Delhi Summary'!B10 -> 18 | C13: ='Delhi Summary'!C10 -> 6 | D13: ='Delhi Summary'!D10 -> 4 | E13: ='Delhi Summary'!E10 -> 2 | F13: ='Delhi Summary'!F10 -> 4 | G13: ='Delhi Summary'!G10 -> 8 | H13: ='Delhi Summary'!H10 -> 8 | ... U13: ='Delhi Summary'!U10 -> 18 | V13: DEL
A14: ='Delhi Summary'!A11 -> TKD | B14: ='Delhi Summary'!B11 -> 17 | C14: ='Delhi Summary'!C11 -> 2 | D14: ='Delhi Summary'!D11 -> 2 | E14: ='Delhi Summary'!E11 -> 33 | F14: ='Delhi Summary'!F11 -> 33 | G14: ='Delhi Summary'!G11 -> 33 | H14: ='Delhi Summary'!H11 -> 33 | ... U14: ='Delhi Summary'!U11 -> 0 | V14: DEL
A15: ='Kolkata Summary'!A4 -> Bandamunda | B15: ='Kolkata Summary'!B4 -> 12 | C15: ='Kolkata Summary'!C4 -> 0 | D15: ='Kolkata Summary'!D4 -> 8 | E15: ='Kolkata Summary'!E4 -> 12 | F15: ='Kolkata Summary'!F4 -> 12 | G15: ='Kolkata Summary'!G4 -> 12 | H15: ='Kolkata Summary'!H4 -> 12 | ... U15: ='Kolkata Summary'!U4 -> 8 | V15: KOL
A16: ='Kolkata Summary'!A5 -> Bhilai | B16: ='Kolkata Summary'!B5 -> 20 | C16: ='Kolkata Summary'!C5 -> 6 | D16: ='Kolkata Summary'!D5 -> 6 | E16: ='Kolkata Summary'!E5 -> 20 | F16: ='Kolkata Summary'!F5 -> 20 | G16: ='Kolkata Summary'!G5 -> 20 | H16: ='Kolkata Summary'!H5 -> 20 | ... U16: ='Kolkata Summary'!U5 -> 18 | V16: KOL
A17: ='Kolkata Summary'!A6 -> BJU | B17: ='Kolkata Summary'!B6 -> 6 | C17: ='Kolkata Summary'!C6 -> 4 | D17: ='Kolkata Summary'!D6 -> 4 | E17: ='Kolkata Summary'!E6 -> 6 | F17: ='Kolkata Summary'!F6 -> 6 | G17: ='Kolkata Summary'!G6 -> 6 | H17: ='Kolkata Summary'!H6 -> 6 | ... U17: ='Kolkata Summary'!U6 -> 4 | V17: KOL
A18: ='Kolkata Summary'!A7 -> Gomoh | B18: ='Kolkata Summary'!B7 -> 40 | C18: ='Kolkata Summary'!C7 -> 32 | D18: ='Kolkata Summary'!D7 -> 31 | E18: ='Kolkata Summary'!E7 -> 40 | F18: ='Kolkata Summary'!F7 -> 40 | G18: ='Kolkata Summary'!G7 -> 40 | H18: ='Kolkata Summary'!H7 -> 40 | ... U18: ='Kolkata Summary'!U7 -> 40 | V18: KOL
A19: ='Kolkata Summary'!A8 -> HWH | B19: ='Kolkata Summary'!B8 -> 74 | C19: ='Kolkata Summary'!C8 -> 70 | D19: ='Kolkata Summary'!D8 -> 70 | E19: ='Kolkata Summary'!E8 -> 74 | F19: ='Kolkata Summary'!F8 -> 74 | G19: ='Kolkata Summary'!G8 -> 74 | H19: ='Kolkata Summary'!H8 -> 74 | ... U19: ='Kolkata Summary'!U8 -> 64 | V19: KOL
A20: ='Kolkata Summary'!A9 -> SDAH | B20: ='Kolkata Summary'!B9 -> 26 | C20: ='Kolkata Summary'!C9 -> 16 | D20: ='Kolkata Summary'!D9 -> 16 | E20: ='Kolkata Summary'!E9 -> 24 | F20: ='Kolkata Summary'!F9 -> 24 | G20: ='Kolkata Summary'!G9 -> 24 | H20: ='Kolkata Summary'!H9 -> 26 | ... U20: ='Kolkata Summary'!U9 -> 8 | V20: KOL
A21: ='Kolkata Summary'!A10 -> SGUJ | B21: ='Kolkata Summary'!B10 -> 2 | C21: ='Kolkata Summary'!C10 -> 0 | D21: ='Kolkata Summary'!D10 -> 0 | E21: ='Kolkata Summary'!E10 -> 2 | F21: ='Kolkata Summary'!F10 -> 2 | G21: ='Kolkata Summary'!G10 -> 2 | H21: ='Kolkata Summary'!H10 -> 2 | ... U21: ='Kolkata Summary'!U10 -> 2 | V21: KOL
A22: ='Kolkata Summary'!A11 -> SPJ | B22: ='Kolkata Summary'!B11 -> 70 | C22: ='Kolkata Summary'!C11 -> 50 | D22: ='Kolkata Summary'!D11 -> 52 | E22: ='Kolkata Summary'!E11 -> 70 | F22: ='Kolkata Summary'!F11 -> 70 | G22: ='Kolkata Summary'!G11 -> 68 | H22: ='Kolkata Summary'!H11 -> 70 | ... U22: ='Kolkata Summary'!U11 -> 66 | V22: KOL
A23: ='Kolkata Summary'!A12 -> SRC | B23: ='Kolkata Summary'!B12 -> 16 | C23: ='Kolkata Summary'!C12 -> 10 | D23: ='Kolkata Summary'!D12 -> 8 | E23: ='Kolkata Summary'!E12 -> 16 | F23: ='Kolkata Summary'!F12 -> 16 | G23: ='Kolkata Summary'!G12 -> 16 | H23: ='Kolkata Summary'!H12 -> 16 | ... U23: ='Kolkata Summary'!U12 -> 16 | V23: KOL
A24: ='Kolkata Summary'!A13 -> Tata | B24: ='Kolkata Summary'!B13 -> 60 | C24: ='Kolkata Summary'!C13 -> 36 | D24: ='Kolkata Summary'!D13 -> 47 | E24: ='Kolkata Summary'!E13 -> 60 | F24: ='Kolkata Summary'!F13 -> 60 | G24: ='Kolkata Summary'!G13 -> 60 | H24: ='Kolkata Summary'!H13 -> 60 | ... U24: ='Kolkata Summary'!U13 -> 52 | V24: KOL
A25: ='Kolkata Summary'!A14 -> Waltier | B25: ='Kolkata Summary'!B14 -> 72 | C25: ='Kolkata Summary'!C14 -> 66 | D25: ='Kolkata Summary'!D14 -> 60 | E25: ='Kolkata Summary'!E14 -> 72 | F25: ='Kolkata Summary'!F14 -> 72 | G25: ='Kolkata Summary'!G14 -> 72 | H25: ='Kolkata Summary'!H14 -> 72 | ... U25: ='Kolkata Summary'!U14 -> 68 | V25: KOL
A26: ='Mumbai Summary'!A4 -> AJNI | B26: ='Mumbai Summary'!B4 -> 54 | C26: ='Mumbai Summary'!C4 -> 27 | D26: ='Mumbai Summary'!D4 -> 34 | E26: ='Mumbai Summary'!E4 -> 51 | F26: ='Mumbai Summary'!F4 -> 54 | G26: ='Mumbai Summary'!G4 -> 28 | H26: ='Mumbai Summary'!H4 -> 54 | ... U26: ='Mumbai Summary'!U4 -> 54 | V26: MUM
A27: ='Mumbai Summary'!A5 -> Itarsi | B27: ='Mumbai Summary'!B5 -> 92 | C27: ='Mumbai Summary'!C5 -> 51 | D27: ='Mumbai Summary'!D5 -> 52 | E27: ='Mumbai Summary'!E5 -> 16 | F27: ='Mumbai Summary'!F5 -> 54 | G27: ='Mumbai Summary'!G5 -> 20 | H27: ='Mumbai Summary'!H5 -> 40 | ... U27: ='Mumbai Summary'!U5 -> 78 | V27: MUM
A28: ='Mumbai Summary'!A6 -> Kalyan | B28: ='Mumbai Summary'!B6 -> 90 | C28: ='Mumbai Summary'!C6 -> 72 | D28: ='Mumbai Summary'!D6 -> 74 | E28: ='Mumbai Summary'!E6 -> 68 | F28: ='Mumbai Summary'!F6 -> 90 | G28: ='Mumbai Summary'!G6 -> 67 | H28: ='Mumbai Summary'!H6 -> 90 | ... U28: ='Mumbai Summary'!U6 -> 71 | V28: MUM
A29: ='Mumbai Summary'!A7 -> Pune | B29: ='Mumbai Summary'!B7 -> 36 | C29: ='Mumbai Summary'!C7 -> 30 | D29: ='Mumbai Summary'!D7 -> 30 | E29: ='Mumbai Summary'!E7 -> 25 | F29: ='Mumbai Summary'!F7 -> 36 | G29: ='Mumbai Summary'!G7 -> 22 | H29: ='Mumbai Summary'!H7 -> 36 | ... U29: ='Mumbai Summary'!U7 -> 20 | V29: MUM
A30: ='Mumbai Summary'!A8 -> Vadodara | B30: ='Mumbai Summary'!B8 -> 120 | C30: ='Mumbai Summary'!C8 -> 66 | D30: ='Mumbai Summary'!D8 -> 120 | E30: ='Mumbai Summary'!E8 -> 118 | F30: ='Mumbai Summary'!F8 -> 116 | G30: ='Mumbai Summary'!G8 -> 24 | H30: ='Mumbai Summary'!H8 -> 24 | ... U30: ='Mumbai Summary'!U8 -> 120 | V30: MUM
A31: ='Mumbai Summary'!A9 -> Valsad | B31: ='Mumbai Summary'!B9 -> 28 | C31: ='Mumbai Summary'!C9 -> 24 | D31: ='Mumbai Summary'!D9 -> 28 | E31: ='Mumbai Summary'!E9 -> 26 | F31: ='Mumbai Summary'!F9 -> 27 | G31: ='Mumbai Summary'!G9 -> 11 | H31: ='Mumbai Summary'!H9 -> 19 | ... U31: ='Mumbai Summary'!U9 -> 28 | V31: MUM
A32: Grand total | B32: =SUM(B2:B31) -> 1558 | C32: =SUM(C2:C31) -> 999 | D32: =SUM(D2:D31) -> 1111 | E32: =SUM(E2:E31) -> 1161 | F32: =SUM(F2:F31) -> 1422 | G32: =SUM(G2:G31) -> 979 | H32: =SUM(H2:H31) -> 1293 | I32: =SUM(I2:I31) -> 1157 | ... U32: =SUM(U2:U31) -> 1283

Sheet Detail1
A1: Details for Removal of metal short link from M9000 with wire - Base Shed: Raipuram
A3: S.No. | B3: Loco no. | C3: HLC | D3: Serial no. of HLC | E3: Base Shed | F3: Railway | G3: Region | H3: DOC | I3: serial no. | J3: Type of Text display | K3: Software version in Conv | L3: Software version in Conv (Master) U7D2S04V.005 (Module) U7F2S240.005 *DATE* | M3: Software version of display | N3: Software version (UAT2Y44O.012) of display updation *DATE* | O3: Filter clean *DATE* | P3: Filter Change *DATE* | Q3: Removal of metal shortlink from M9000 with wire | R3: Replacement of 10 amp fuse with 20amp | S3: Shifting of wires on O/P contactor | T3: External earth fault wire modification | U3: Shifting of wires of output voltage available lamp | V3: Sealing of cable entry of panel | W3: Sealing of main fan plate (On which DC-DC converter installed) | X3: Mounting of 110 volt DC fan on PWR | Y3: Air leakage status in duct at the back of the converter | Z3: FG block removal from bottom of input choke | AA3: Surge arrestor fitment | AB3: Input choke change (mention sr.no. of new choke_ | AC3: O/P choke change (mention sr.no. of new choke_ | AD3: Control fuse 6.5amp to 15amp (Glass fuse) | AE3: Display button | AF3: DC link bus bar supporter | AG3: Software version in Conv (171022) (Master) W812N04V.005 (Module) W812N240.005 *DATE* | AH3: New Software version (UAT2Y44O.012) of display updation *DATE* | AI3: Sine Filter Capacitor washer fitment and tightness of connection *DATE* | AJ3: ELR setting to check (1amp /10 sec) | AK3: Heat Sink Cleaning *Date*
A4: 96 | B4: 37143 | C4: HLC-B | D4: STB2L0412HLCD | E4: Raipuram | F4: SR | G4: CHE | H4: 43571 | I4: 412 | J4: Nashik | K4: M-U7D2S04V.005, MO-U7F2S240.005 | L4: 44180 | M4: UAT2Y440.012 | N4: 44180 | O4: 45148 | Q4: Con-B done | R4: Conv-B DONE | T4: Conv-B DONE | U4: Conv-B DONE | Y4: Conv-B DONE | Z4: Conv-B DONE | AD4: Conv-B DONE | AI4: 45215 | AJ4: Done
A5: 77 | B5: 30482 | C5: HLC-A | D5: STB8F0022HLDA | E5: Raipuram | F5: SR | G5: CHE | H5: 42570 | I5: 22 | J5: Imported | K5: M-U7D2S04V.005, MO-U7F2S240.005 | L5: Done | M5: L3I2ZY72.008 | N5: Done | O5: 45056 | P5: 44699 | Q5: Conv-A DONE | R5: Conv-A DONE | T5: Conv-A DONE | Y5: Conv-A DONE | Z5: Conv-A DONE | AD5: Conv-A DONE | AJ5: Done
A6: 79 | B6: 30528 | C6: HLC-A | D6: STB7H0068HLCC | E6: Raipuram | F6: SR | G6: CHE | H6: 42849 | I6: 68 | J6: Imported | K6: M-U7D2S04V.005, MO-U7F2S240.005 | L6: 44265 | M6: UAT2Y440.012 | N6: 44265 | O6: 45071 | P6: 44700 | Q6: Conv-A DONE | R6: Conv-A DONE | T6: Conv-A DONE | Y6: Conv-A DONE | Z6: Conv-A DONE | AD6: Conv-A DONE | AI6: 45166 | AJ6: Done
A7: 85 | B7: 30615 | C7: HLC-A | D7: STB8J0137HLCD | E7: Raipuram | F7: SR | G7: CHE | H7: 43071 | I7: 137 | J7: Nashik | K7: M-U7D2S04V.005, MO-U7F2S240.005 | L7: 44185 | M7: UAT2Y440.012 | N7: 44185 | Q7: Conv-A DONE | R7: Conv-A DONE | S7: Conv-A DONE | T7: Conv-A DONE | U7: Conv-A DONE | Z7: Conv-A DONE | AD7: Conv-A DONE | AF7: Conv-A DONE
A8: 78 | B8: 30482 | C8: HLC-B | D8: STB8F0046HLDA | E8: Raipuram | F8: SR | G8: CHE | H8: 42570 | I8: 46 | J8: Imported | K8: M-U7D2S04V.005, MO-U7F2S240.005 | L8: Done | M8: L3I2ZY72.008 | N8: Done | O8: 45056 | P8: 44699 | Q8: Conv-B DONE | R8: Conv-B DONE | T8: Conv-B DONE | Y8: Conv-B DONE | Z8: Conv-B DONE | AD8: Conv-B DONE | AJ8: Done
A9: 80 | B9: 30528 | C9: HLC-B | D9: STB7H0071HLCC | E9: Raipuram | F9: SR | G9: CHE | H9: 42849 | I9: 71 | J9: Imported | K9: M-U7D2S04V.005, MO-U7F2S240.005 | L9: 44265 | M9: UAT2Y440.012 | N9: 44265 | O9: 45071 | P9: 44700 | Q9: Conv-B DONE | R9: Conv-B DONE | T9: Conv-B DONE | Y9: Conv-B DONE | Z9: Conv-B DONE | AD9: Conv-B DONE | AI9: 45166 | AJ9: Done
A10: 86 | B10: 30615 | C10: HLC-B | D10: STB9J0157HLCD | E10: Raipuram | F10: SR | G10: CHE | H10: 43071 | I10: 157 | J10: Nashik | K10: M-U7D2S04V.005, MO-U7F2S240.005 | L10: 44185 | M10: UAT2Y440.012 | N10: 44185 | Q10: Conv-B DONE | R10: Conv-B DONE | S10: Conv-B DONE | T10: Conv-B DONE | U10: Conv-B DONE | Z10: Conv-B DONE | AD10: Conv-B DONE | AF10: Conv-B DONE
B11: 30390 | C11: HLC-B | D11: STBDP1384HLCD | E11: Raipuram | F11: SR | G11: CHE | H11: 45216 | I11: 1384 | J11: Nashik | Q11: Done by NW | R11: Done by NW | S11: Done by NW | T11: Done by NW | U11: Done by NW | X11: Done by NW | AD11: Done by NW | AF11: Done by NW | AJ11: Done
A12: 194 | B12: 30390 | C12: HLC-A | D12: STBDP1387HLCD | E12: Raipuram | F12: SR | G12: CHE | H12: 45216 | I12: 1387 | J12: Nashik | Q12: Done by NW | R12: Done by NW | S12: Done by NW | T12: Done by NW | U12: Done by NW | X12: Done by NW | AD12: Done by NW | AF12: Done by NW | AJ12: Done
B13: 30419 | C13: HLC-B | D13: STB9P1346HLCD | E13: Raipuram | F13: SR | G13: CHE | H13: 45192 | I13: 1346 | J13: Nashik | Q13: Done by NW | R13: Done by NW | S13: Done by NW | T13: Done by NW | U13: Done by NW | X13: Done by NW | AD13: Done by NW | AF13: Done by NW | AI13: 45192 | AJ13: Done
A14: 193 | B14: 30419 | C14: HLC-A | D14: STB9P1357HLCD | E14: Raipuram | F14: SR | G14: CHE | H14: 45192 | I14: 1357 | J14: Nashik | Q14: Done by NW | R14: Done by NW | S14: Done by NW | T14: Done by NW | U14: Done by NW | X14: Done by NW | AD14: Done by NW | AF14: Done by NW | AI14: 45192 | AJ14: Done
B15: 30409 | C15: HLC-B | D15: STBDN1183HLCD | E15: Raipuram | F15: SR | G15: CHE | H15: 45177 | I15: 1183 | J15: Nashik | Q15: Done by NW | R15: Done by NW | S15: Done by NW | T15: Done by NW | U15: Done by NW | X15: Done by NW | AD15: Done by NW | AF15: Done by NW | AI15: 45177 | AJ15: Done
A16: 192 | B16: 30409 | C16: HLC-A | D16: STB9P1348HLCD | E16: Raipuram | F16: SR | G16: CHE | H16: 45177 | I16: 1348 | J16: Nashik | Q16: Done by NW | R16: Done by NW | S16: Done by NW | T16: Done by NW | U16: Done by NW | X16: Done by NW | AD16: Done by NW | AF16: Done by NW | AI16: 45177 | AJ16: Done
B17: 30424 | C17: HLC-B | D17: STBDP1339HLCD | E17: Raipuram | F17: SR | G17: CHE | H17: 45163 | I17: 1339 | J17: Nashik | M17: Done by NW | N17: Done by NW | Q17: Done by NW | R17: Done by NW | S17: Done by NW | T17: Done by NW | U17: Done by NW | X17: Done by NW | Z17: Done by NW | AD17: Done by NW | AF17: Done by NW | AI17: 45162 | AJ17: Done
A18: 190 | B18: 30424 | C18: HLC-A | D18: STBDP1338HLCD | E18: Raipuram | F18: SR | G18: CHE | H18: 45163 | I18: 1338 | J18: Nashik | M18: Done by NW | N18: Done by NW | Q18: Done by NW | R18: Done by NW | S18: Done by NW | T18: Done by NW | U18: Done by NW | X18: Done by NW | Z18: Done by NW | AD18: Done by NW | AF18: Done by NW | AI18: 45162 | AJ18: Done
B19: 30342 | C19: HLC-B | D19: STBDP1389HLCD | E19: Raipuram | F19: SR | G19: CHE | H19: 45125 | I19: 1389 | J19: Nashik | M19: Done by NW | N19: Done by NW | Q19: Done by NW | R19: Done by NW | S19: Done by NW | T19: Done by NW | U19: Done by NW | X19: Done by NW | Z19: Done by NW | AD19: Done by NW | AF19: Done by NW | AI19: 45197 | AJ19: Done
A20: 189 | B20: 30342 | C20: HLC-A | D20: STBDP1385HLCD | E20: Raipuram | F20: SR | G20: CHE | H20: 45125 | I20: 1385 | J20: Nashik | M20: Done by NW | N20: Done by NW | Q20: Done by NW | R20: Done by NW | S20: Done by NW | T20: Done by NW | U20: Done by NW | X20: Done by NW | Z20: Done by NW | AD20: Done by NW | AF20: Done by NW | AI20: 45197 | AJ20: Done
B21: 30393 | C21: HLC-B | D21: STB9P1354HLCD | E21: Raipuram | F21: SR | G21: CHE | H21: 45110 | I21: 1354 | J21: Nashik | M21: Done by NW | N21: Done by NW | Q21: Done by NW | R21: Done by NW | S21: Done by NW | T21: Done by NW | U21: Done by NW | X21: Done by NW | Z21: Done by NW | AD21: Done by NW | AF21: Done by NW | AG21: 45218 | AJ21: Done
A22: 188 | B22: 30393 | C22: HLC-A | D22: STB9P1359HLCD | E22: Raipuram | F22: SR | G22: CHE | H22: 45110 | I22: 1359 | J22: Nashik | M22: Done by NW | N22: Done by NW | Q22: Done by NW | R22: Done by NW | S22: Done by NW | T22: Done by NW | U22: Done by NW | X22: Done by NW | Z22: Done by NW | AD22: Done by NW | AF22: Done by NW | AG22: 45218 | AJ22: Done
B23: 30392 | C23: HLC-B | D23: STBDN1180HLCD | E23: Raipuram | F23: SR | G23: CHE | H23: 45110 | I23: 1180 | J23: Nashik | M23: Done by NW | N23: Done by NW | Q23: Done by NW | R23: Done by NW | S23: Done by NW | T23: Done by NW | U23: Done by NW | X23: Done by NW | Z23: Done by NW | AD23: Done by NW | AF23: Done by NW | AI23: 45204 | AJ23: Done
A24: 187 | B24: 30392 | C24: HLC-A | D24: STBOP1361HLCD | E24: Raipuram | F24: SR | G24: CHE | H24: 45110 | I24: 1361 | J24: Nashik | M24: Done by NW | N24: Done by NW | Q24: Done by NW | R24: Done by NW | S24: Done by NW | T24: Done by NW | U24: Done by NW | X24: Done by NW | Z24: Done by NW | AD24: Done by NW | AF24: Done by NW | AI24: 45204 | AJ24: Done
B25: 30411 | C25: HLC-B | D25: STBDN1181HLCD | E25: Raipuram | F25: SR | G25: CHE | H25: 45085 | I25: 1181 | J25: Nashik | M25: Done by NW | N25: Done by NW | Q25: Done by NW | R25: Done by NW | S25: Done by NW | T25: Done by NW | U25: Done by NW | X25: Done by NW | Z25: Done by NW | AD25: Done by NW | AF25: Done by NW | AI25: NA | AJ25: Done
A26: 186 | B26: 30411 | C26: HLC-A | D26: STB9P1351HLCD | E26: Raipuram | F26: SR | G26: CHE | H26: 45085 | I26: 1351 | J26: Nashik | M26: Done by NW | N26: Done by NW | Q26: Done by NW | R26: Done by NW | S26: Done by NW | T26: Done by NW | U26: Done by NW | X26: Done by NW | Z26: Done by NW | AD26: Done by NW | AF26: Done by NW | AI26: NA | AJ26: Done
B27: 30378 | C27: HLC-B | D27: STBDP1382HLCD | E27: Raipuram | F27: SR | G27: CHE | H27: 45058 | I27: 1382 | J27: Nashik | M27: Done by NW | N27: Done by NW | Q27: Done by NW | R27: Done by NW | S27: Done by NW | T27: Done by NW | U27: Done by NW | X27: Done by NW | Z27: Done by NW | AD27: Done by NW | AF27: Done by NW | AJ27: Done
A28: 185 | B28: 30378 | C28: HLC-A | D28: STBDP1380HLCD | E28: Raipuram | F28: SR | G28: CHE | H28: 45058 | I28: 1380 | J28: Nashik | M28: Done by NW | N28: Done by NW | Q28: Done by NW | R28: Done by NW | S28: Done by NW | T28: Done by NW | U28: Done by NW | X28: Done by NW | Z28: Done by NW | AD28: Done by NW | AF28: Done by NW | AJ28: Done
B29: 39240 | C29: HLC-B | D29: STB3P1259HLCD | E29: Raipuram | F29: SR | G29: CHE | H29: 45040 | I29: 1259 | J29: Nashik | M29: Done by NW | N29: Done by NW | Q29: Done by NW | R29: Done by NW | S29: Done by NW | T29: Done by NW | U29: Done by NW | X29: Done by NW | Z29: Done by NW | AD29: Done by NW | AF29: Done by NW | AI29: 45195 | AJ29: Done
A30: 184 | B30: 39240 | C30: HLC-A | D30: STB3P1265HLCD | E30: Raipuram | F30: SR | G30: CHE | H30: 45040 | I30: 1265 | J30: Nashik | M30: Done by NW | N30: Done by NW | Q30: Done by NW | R30: Done by NW | S30: Done by NW | T30: Done by NW | U30: Done by NW | X30: Done by NW | Z30: Done by NW | AD30: Done by NW | AF30: Done by NW | AI30: 45195 | AJ30: Done
B31: 37600 | C31: HLC-B | D31: STB4P1301HLCD | E31: Raipuram | F31: SR | G31: CHE | H31: 45016 | I31: 1301 | J31: Nashik | Q31: Done by NW | R31: Done by NW | S31: Done by NW | T31: Done by NW | U31: Done by NW | X31: Done by NW | Z31: Done by NW | AD31: Done by NW | AF31: Done by NW | AJ31: Done
A32: 183 | B32: 37600 | C32: HLC-A | D32: STB4P1295HLCD | E32: Raipuram | F32: SR | G32: CHE | H32: 45016 | I32: 1295 | J32: Nashik | Q32: Done by NW | R32: Done by NW | S32: Done by NW | T32: Done by NW | U32: Done by NW | X32: Done by NW | Z32: Done by NW | AD32: Done by NW | AF32: Done by NW | AJ32: Done
B33: 39237 | C33: HLC-B | D33: STB3P1255HLCD | E33: Raipuram | F33: SR | G33: CHE | H33: 45008 | I33: 1255 | J33: Nashik | Q33: Done by NW | R33: Done by NW | S33: Done by NW | T33: Done by NW | U33: Done by NW | X33: Done by NW | Z33: Done by NW | AD33: Done by NW | AF33: Done by NW | AJ33: Done
A34: 182 | B34: 39237 | C34: HLC-A | D34: STB3P1258HLCD | E34: Raipuram | F34: SR | G34: CHE | H34: 45008 | I34: 1258 | J34: Nashik | Q34: Done by NW | R34: Done by NW | S34: Done by NW | T34: Done by NW | U34: Done by NW | X34: Done by NW | Z34: Done by NW | AD34: Done by NW | AF34: Done by NW | AJ34: Done
B35: 30367 | C35: HLC-B | D35: STBDP1386HLCD | E35: Raipuram | F35: SR | G35: CHE | H35: 45005 | I35: 1386 | J35: Nashik | Q35: Done by NW | R35: Done by NW | S35: Done by NW | T35: Done by NW | U35: Done by NW | X35: Done by NW | Z35: Done by NW | AD35: Done by NW | AF35: Done by NW | AI35: 45196 | AJ35: Done
A36: 181 | B36: 30367 | C36: HLC-A | D36: STBDP1388HLCD | E36: Raipuram | F36: SR | G36: CHE | H36: 45005 | I36: 1388 | J36: Nashik | Q36: Done by NW | R36: Done by NW | S36: Done by NW | T36: Done by NW | U36: Done by NW | X36: Done by NW | Z36: Done by NW | AD36: Done by NW | AF36: Done by NW | AI36: 45196 | AJ36: Done
A37: 180 | B37: 30421 | C37: HLC-B | D37: STBDP1390HLCD | E37: Raipuram | F37: SR | G37: CHE | H37: 44993 | I37: 1390 | J37: Nashik | K37: M-U7D2S04V.005, MO-U7F2S240.005 | L37: Done by NW | M37: UAT2Y440.012 | N37: Done by NW | Q37: Done by NW | R37: Done by NW | S37: Done by NW | T37: Done by NW | U37: Done by NW | X37: Done by NW | Z37: Done by NW | AD37: Done by NW | AF37: Done by NW
A38: 179 | B38: 30421 | C38: HLC-A | D38: STBDP1391HLCD | E38: Raipuram | F38: SR | G38: CHE | H38: 44993 | I38: 1391 | J38: Nashik | K38: M-U7D2S04V.005, MO-U7F2S240.005 | L38: Done by NW | M38: UAT2Y440.012 | N38: Done by NW | Q38: Done by NW | R38: Done by NW | S38: Done by NW | T38: Done by NW | U38: Done by NW | X38: Done by NW | Z38: Done by NW | AD38: Done by NW | AF38: Done by NW
A39: 178 | B39: 39229 | C39: HLC-B | D39: STB2P1232HLCD | E39: Raipuram | F39: SR | G39: CHE | H39: 44977 | I39: 1232 | J39: Nashik | K39: M-U7D2S04V.005, MO-U7F2S240.005 | L39: Done by NW | M39: UAT2Y440.012 | N39: Done by NW | Q39: Done by NW | R39: Done by NW | S39: Done by NW | T39: Done by NW | U39: Done by NW | X39: Done by NW | Z39: Done by NW | AD39: Done by NW | AF39: Done by NW | AI39: 45167 | AJ39: Done
A40: 177 | B40: 39229 | C40: HLC-A | D40: STB2P1235HLCD | E40: Raipuram | F40: SR | G40: CHE | H40: 44977 | I40: 1235 | J40: Nashik | K40: M-U7D2S04V.005, MO-U7F2S240.005 | L40: Done by NW | M40: UAT2Y440.012 | N40: Done by NW | Q40: Done by NW | R40: Done by NW | S40: Done by NW | T40: Done by NW | U40: Done by NW | X40: Done by NW | Z40: Done by NW | AD40: Done by NW | AF40: Done by NW | AI40: 45167 | AJ40: Done
A41: 176 | B41: 39228 | C41: HLC-B | D41: STB2P1239HLCD | E41: Raipuram | F41: SR | G41: CHE | H41: 44972 | I41: 1239 | J41: Nashik | K41: M-U7D2S04V.005, MO-U7F2S240.005 | L41: Done by NW | M41: UAT2Y440.012 | N41: Done by NW | Q41: Done by NW | R41: Done by NW | S41: Done by NW | T41: Done by NW | U41: Done by NW | X41: Done by NW | Z41: Done by NW | AD41: Done by NW | AF41: Done by NW | AI41: 45167 | AJ41: Done
...

Sheet Hyderabad
A1: S.No. | B1: Loco no. | C1: HLC | D1: Serial no. of HLC | E1: Base Shed | F1: Railway | G1: Region | H1: DOC | I1: serial no. | J1: Type of Text display | K1: Software version in Conv | L1: Software version in Conv (Master) U7D2S04V.005 (Module) U7F2S240.005 *DATE* | M1: Software version of display | N1: Software version (UAT2Y440.012) of display updation *DATE* | O1: Filter clean *DATE* | P1: Filter Change *DATE* | Q1: Removal of metal shortlink from M9000 with wire | R1: Replacement of 10 amp fuse with 20amp | S1: Shifting of wires on O/P contactor | T1: External earth fault wire modification | U1: Shifting of wires of output voltage available lamp | V1: Sealing of cable entry of panel | W1: Sealing of main fan plate (On which DC-DC converter installed) | X1: Mounting of 110 volt DC fan on PWR | Y1: Air leakage status in duct at the back of the converter | Z1: FG block removal from bottom of input choke | AA1: Surge arrestor fitment | AB1: Input choke change (mention sr.no. of new choke_ | AC1: O/P choke change (mention sr.no. of new choke_ | AD1: Control fuse 6.5amp to 15amp (Glass fuse) | AE1: Display button | AF1: DC link bus bar supporter | AG1: Software version in Conv (200622) (Master) Y6U2N04V.006 (Module) Y6U2N240.005 *DATE* | AH1: New Software version (UAT2Y44O.012) of display updation *DATE* | AI1: Sine Filter Capacitor washer fitment and tightness of connection *DATE* | AJ1: ELR setting to check (1amp /10 sec) | AK1: Heat Sink Cleaning *Date* | AL1: I/P contactor SILICON washer | AM1: Steel mesh on cyclonic filter on looc wall | AN1: Installation of new type of communication card on display | AQ1: HMI software update by NW from panel | AR1: STBOM1026
A2: 1 | B2: 30587 | C2: HLC-A | D2: STB5J0099HLCC | E2: Lallaguda | F2: SCR | G2: HYD | H2: 42942 | J2: Nashik | K2: M-U7D2S04V.005, | L2: Done | M2: UAT2Y440.012 | N2: 44195 | Q2: Done | R2: Conv-A DONE | T2: Conv-A DONE | U2: Conv-A DONE | AD2: Done | AE2: DONE | AF2: 25-07-2025 | AG2: 45359 | AH2: 45359 | AI2: 25-07-2024 | AJ2: DONE | AK2: 25-07-2024 | AM2: 18-11-2024
A3: 2 | B3: 30587 | C3: HLC-B | D3: STB5J0096HLCC | E3: Lallaguda | F3: SCR | G3: HYD | H3: 42942 | J3: Nashik | K3: M-U7D2S04V.005, | L3: Done | M3: UAT2Y440.012 | N3: Done | Q3: Done | R3: Conv-B DONE | T3: Conv-B DONE | U3: Conv-B DONE | AD3: Done | AE3: DONE | AF3: 25-07-2024 | AG3: 45359 | AH3: 45359 | AI3: 25-07-2024 | AJ3: DONE | AK3: 25-07-2024 | AM3: 18-11-2024
A4: 3 | B4: 30595 | C4: HLC-A | D4: STB7J0131HLCD | E4: Lallaguda | F4: SCR | G4: HYD | H4: 43054 | J4: Nashik | K4: M-U7D2S04V.005, | L4: Done | M4: UAT2Y440.012 | N4: 44191 | Q4: Done | R4: Conv-A DONE | T4: Conv-A DONE | U4: Conv-A DONE | AE4: DONE | AF4: 13-07-2024 | AG4: 15-07-2024 | AH4: 15-07-2024 | AI4: 13-07-2024 | AJ4: DONE | AK4: 13-07-2024 | AM4: 18-06-2024
A5: 4 | B5: 30595 | C5: HLC-B | D5: STB7J0130HLCD | E5: Lallaguda | F5: SCR | G5: HYD | H5: 43054 | J5: Nashik | K5: M-U7D2S04V.005, | L5: Done | M5: UAT2Y440.012 | N5: 44219 | Q5: Done | R5: Conv-B DONE | T5: Conv-B DONE | U5: Conv-B DONE | AE5: DONE | AF5: 13-07-2024 | AG5: 15-07-2024 | AH5: 15-07-2024 | AI5: 13-07-2024 | AJ5: DONE | AK5: 13-07-2024 | AM5: 18-06-2024
A6: 5 | B6: 30596 | C6: HLC-A | D6: STB5J0097HLCD | E6: Lallaguda | F6: SCR | G6: HYD | H6: 43026 | J6: Nashik | K6: M-U7D2S04V.005, | L6: Done | M6: UAT2Y440.012 | N6: Done | Q6: Done | R6: Conv-B DONE | T6: Conv-A DONE | U6: Conv-A DONE | AD6: Done | AE6: DONE | AF6: 22-07-2024 | AG6: 24-07-2024 | AH6: 24-07-2024 | AI6: 22-07-2024 | AJ6: DONE | AK6: 22-07-2024 | AM6: 45514
A7: 6 | B7: 30596 | C7: HLC-B | D7: STB5J0098HLCD | E7: Lallaguda | F7: SCR | G7: HYD | H7: 43026 | J7: Nashik | K7: M-U7D2S04V.005, | L7: Done | M7: UAT2Y440.012 | N7: 44270 | Q7: Done | R7: Conv-A DONE | T7: Conv-B DONE | U7: Conv-B DONE | AD7: Done | AE7: DONE | AF7: 22-07-2024 | AG7: 24-07-2024 | AH7: 24-07-2024 | AI7: 22-07-2024 | AJ7: DONE | AK7: 22-07-2024 | AM7: 45514
A8: 7 | B8: 30602 | C8: HLC-A | D8: STB8J0148HLCD | E8: BZA | F8: SCR | G8: HYD | H8: 43053 | J8: Nashik | K8: M-U7D2S04V.005, | L8: Done | M8: UAT2Y440.012 | N8: Done | Q8: Done | R8: Conv-A DONE | T8: Conv-A DONE | U8: Conv-A DONE | AG8: 28-06-2024 | AH8: 28-06-2024 | AI8: 27-06-2024 | AJ8: DONE | AK8: 27-06-2024
A9: 8 | B9: 30602 | C9: HLC-B | D9: STB8J0149HLCD | E9: BZA | F9: SCR | G9: HYD | H9: 43053 | J9: Nashik | K9: M-U7D2S04V.005, | L9: Done | M9: UAT2Y440.012 | N9: 44183 | Q9: Done | R9: Conv-B DONE | T9: Conv-B DONE | U9: Conv-B DONE | AB9: 44523 | AG9: 28-06-2024 | AH9: 28-06-2024 | AI9: 27-06-2024 | AJ9: DONE | AK9: 27-06-2024
A10: 9 | B10: 30603 | C10: HLC-A | D10: STB8J0150HLCD | E10: Lallaguda | F10: SCR | G10: HYD | H10: 43064 | J10: Nashik | K10: M-U7D2S04V.005, | L10: Done | M10: UAT2Y440.012 | N10: 44176 | Q10: Done | R10: Conv-A DONE | T10: Conv-A DONE | U10: Conv-A DONE | AB10: 44778 | AD10: Done | AE10: DONE | AF10: 45455 | AG10: 13-07-2024 | AH10: 13-07-2024 | AI10: 45603 | AJ10: DONE | AK10: 45603 | AM10: 45455
A11: 10 | B11: 30603 | C11: HLC-B | D11: STB8J0151HLCD | E11: Lallaguda | F11: SCR | G11: HYD | H11: 43064 | J11: Nashik | K11: M-U7D2S04V.005, | L11: Done | M11: UAT2Y440.012 | N11: 44180 | Q11: Done | R11: Conv-B DONE | T11: Conv-B DONE | U11: Conv-B DONE | AB11: 44236 | AD11: Done | AE11: DONE | AF11: 45455 | AG11: 13-07-2024 | AH11: 13-07-2024 | AI11: 45603 | AJ11: DONE | AK11: 45603 | AM11: 45455
A12: 11 | B12: 30605 | C12: HLC-A | D12: STB7J0120HLCD | E12: BZA | F12: SCR | G12: HYD | H12: 43060 | J12: Nashik | K12: M-U7D2S04V.005, | L12: Done | M12: UAT2Y440.012 | N12: 44177 | Q12: Done | R12: Conv-A DONE | T12: Conv-A DONE | U12: Conv-A DONE | AB12: 44778 | AD12: Done | AE12: DONE | AG12: 31-07-2024 | AH12: 31-07-2024 | AI12: 31-07-2024 | AJ12: DONE | AK12: 31-07-2024
A13: 12 | B13: 30605 | C13: HLC-B | D13: STB7J0121HLCD | E13: BZA | F13: SCR | G13: HYD | H13: 43060 | J13: Nashik | K13: M-U7D2S04V.005, | L13: Done | M13: UAT2Y440.012 | N13: Done | Q13: Done | R13: Conv-B DONE | T13: Conv-B DONE | U13: Conv-B DONE | AB13: 44301 | AD13: Done | AE13: DONE | AG13: 31-07-2024 | AH13: 31-07-2024 | AI13: 31-07-2024 | AJ13: DONE | AK13: 31-07-2024
A14: 13 | B14: 30610 | C14: HLC-A | D14: STB7J0129HLCD | E14: BZA | F14: SCR | G14: HYD | H14: 43082 | J14: Nashik | K14: M-U7D2S04V.005, | L14: Done | M14: UAT2Y440.012 | N14: 44193 | Q14: Done | R14: Conv-A DONE | T14: Conv-A DONE | U14: Conv-A DONE | AG14: 22-07-2024 | AH14: 22-07-2024 | AI14: 22-07-2024 | AJ14: DONE | AK14: 22-07-2024 | AM14: 26-10-2024
A15: 14 | B15: 30610 | C15: HLC-B | D15: STB1J0156HLCD | E15: BZA | F15: SCR | G15: HYD | H15: 43082 | J15: Nashik | K15: M-U7D2S04V.005, | L15: Done | M15: UAT2Y440.012 | N15: 44191 | Q15: Done | R15: Conv-B DONE | T15: Conv-B DONE | U15: Conv-B DONE | AB15: 44512 | AG15: 22-07-2024 | AH15: 22-07-2024 | AI15: 22-07-2024 | AJ15: DONE | AK15: 22-07-2024 | AM15: 26-10-2024
A16: 15 | B16: 30611 | C16: HLC-A | D16: STB9J0159HLCD | E16: Lallaguda | F16: SCR | G16: HYD | H16: 43068 | J16: Nashik | K16: M-U7D2S04V.005, | L16: Done | M16: UAT2Y440.012 | N16: 44215 | Q16: Done | R16: Conv-A DONE | T16: Conv-A DONE | U16: Conv-A DONE | AB16: 44721 | AE16: DONE | AF16: 45901 | AG16: 45298 | AH16: 45298 | AI16: 25-06-2024 | AJ16: DONE | AK16: 25-06-2024 | AM16: 28-06-2024
A17: 16 | B17: 30611 | C17: HLC-B | D17: STB8J0136HLCD | E17: Lallaguda | F17: SCR | G17: HYD | H17: 43068 | J17: Nashik | K17: M-U7D2S04V.005, | L17: Done | M17: UAT2Y440.012 | N17: 44238 | Q17: Done | R17: Conv-B DONE | T17: Conv-B DONE | U17: Conv-B DONE | AB17: 44806 | AE17: DONE | AF17: 45901 | AG17: 45298 | AH17: 45298 | AI17: 25-06-2024 | AJ17: DONE | AK17: 25-06-2024 | AM17: 28-06-2024
A18: 17 | B18: 30612 | C18: HLC-A | D18: STB6J0118HLCD | E18: BZA | F18: SCR | G18: HYD | H18: 43100 | J18: Nashik | K18: M-U7D2S04V.005, | L18: Done | M18: UAT2Y440.012 | N18: 44217 | Q18: Done | R18: Conv-A DONE | T18: Conv-A DONE | U18: Conv-A DONE | AD18: Done | AE18: DONE | AG18: 19-07-2024 | AH18: 19-07-2024 | AI18: 19-07-2024 | AJ18: DONE | AK18: 45481 | AM18: 20-09-2024
A19: 18 | B19: 30612 | C19: HLC-B | D19: STB6J0108HLCD | E19: BZA | F19: SCR | G19: HYD | H19: 43100 | J19: Nashik | K19: M-U7D2S04V.005, | L19: Done | M19: UAT2Y440.012 | N19: 44200 | Q19: Done | R19: Conv-B DONE | T19: Conv-B DONE | U19: Conv-B DONE | AD19: Done | AE19: DONE | AG19: 19-07-2024 | AH19: 19-07-2024 | AI19: 19-07-2024 | AJ19: DONE | AK19: 45481 | AM19: 20-09-2024
A20: 19 | B20: 30613 | C20: HLC-A | D20: STB9J0164HLCD | E20: BZA | F20: SCR | G20: HYD | H20: 43130 | J20: Nashik | K20: M-U7D2S04V.005, | L20: Done | M20: UAT2Y440.012 | N20: 44217 | Q20: Done | R20: Conv-A DONE | T20: Conv-A DONE | U20: Conv-A DONE | AD20: Done | AG20: 22-06-2024 | AH20: 22-06-2024 | AI20: 22-06-2024 | AJ20: DONE | AK20: 26-06-2024 | AM20: 26-09-2024
A21: 20 | B21: 30613 | C21: HLC-B | D21: STB9J0165HLCD | E21: BZA | F21: SCR | G21: HYD | H21: 43130 | J21: Nashik | K21: M-U7D2S04V.005, | L21: Done | M21: UAT2Y440.012 | N21: 44300 | O21: 44086 | Q21: Done | R21: Conv-B DONE | T21: Conv-B DONE | U21: Conv-B DONE | W21: Conv-B DONE | AD21: Done | AG21: 22-06-2024 | AH21: 22-06-2024 | AI21: 22-06-2024 | AJ21: DONE | AK21: 26-06-2024 | AM21: 26-09-2024
A22: 21 | B22: 30617 | C22: HLC-A | D22: STB8J0143HLCD | E22: BZA | F22: SCR | G22: HYD | H22: 43102 | J22: Nashik | K22: M-U7D2S04V.005, | L22: Done | M22: UAT2Y440.012 | N22: 44301 | Q22: Done | R22: Conv-A DONE | T22: Conv-A DONE | U22: Conv-A DONE | AD22: Done | AE22: DONE | AG22: 45574 | AH22: 45574 | AI22: 45574 | AJ22: DONE | AK22: 45638 | AM22: 45574
A23: 22 | B23: 30617 | C23: HLC-B | D23: STB8J0142HLCD | E23: BZA | F23: SCR | G23: HYD | H23: 43102 | J23: Nashik | K23: M-U7D2S04V.005, | L23: Done | M23: UAT2Y440.012 | N23: 44230 | Q23: Done | R23: Conv-B DONE | T23: Conv-B DONE | U23: Conv-B DONE | AD23: Done | AE23: DONE | AG23: 45574 | AH23: 45574 | AI23: 45574 | AJ23: DONE | AK23: 45638 | AM23: 45574
A24: 23 | B24: 30618 | C24: HLC-A | D24: STB6J0119HLCD | E24: BZA | F24: SCR | G24: HYD | H24: 43099 | J24: Nashik | K24: M-U7D2S04V.005, | L24: Done | M24: UAT2Y440.012 | N24: 44263 | Q24: Done | R24: Conv-A DONE | T24: Conv-A DONE | U24: Conv-A DONE | AD24: Done | AE24: DONE | AG24: 45634 | AH24: 41251 | AI24: 45634 | AJ24: DONE | AK24: 45573
A25: 24 | B25: 30618 | C25: HLC-B | D25: STB6J0109HLCD | E25: BZA | F25: SCR | G25: HYD | H25: 43099 | J25: Nashik | K25: M-U7D2S04V.005, | L25: Done | M25: UAT2Y440.012 | N25: 44280 | Q25: Done | R25: Conv-B DONE | T25: Conv-B DONE | U25: Conv-B DONE | AD25: Done | AE25: DONE | AG25: 45634 | AH25: 45634 | AI25: 45634 | AJ25: DONE | AK25: 45573
A26: 25 | B26: 37062 | C26: HLC-A | D26: STB2K0180HLCD | E26: Lallaguda | F26: SCR | G26: HYD | H26: 43456 | J26: Nashik | K26: M-U7D2S04V.005, | L26: Done | M26: UAT2Y440.012 | N26: 44176 | Q26: Done | R26: Conv-A DONE | T26: Conv-A DONE | U26: Conv-A DONE | AD26: Done | AE26: DONE | AF26: 45573 | AG26: 45573 | AH26: 45573 | AI26: 45573 | AJ26: DONE | AK26: 45573 | AM26: 13-06-2024
A27: 26 | B27: 37062 | C27: HLC-B | D27: STB3K0196HLCD | E27: Lallaguda | F27: SCR | G27: HYD | H27: 43456 | J27: Nashik | K27: M-U7D2S04V.005, | L27: Done | M27: UAT2Y440.012 | N27: 44184 | Q27: Done | R27: Conv-B DONE | T27: Conv-B DONE | U27: Conv-B DONE | AB27: 44408 | AD27: Done | AE27: DONE | AF27: 45573 | AG27: 45573 | AH27: 45573 | AI27: 45573 | AJ27: DONE | AK27: 45573 | AM27: 13-06-2024
A28: 27 | B28: 37085 | C28: HLC-A | D28: STB6K0258HLCD | E28: Lallaguda | F28: SCR | G28: HYD | H28: 43507 | J28: Nashik | K28: M-U7D2S04V.005, | L28: Done | M28: UAT2Y440.012 | N28: 44214 | Q28: Done | R28: Conv-A DONE | T28: Conv-A DONE | U28: Conv-A DONE | AB28: 44020 | AE28: DONE | AF28: 16-07-2024 | AG28: 18-07-2024 | AH28: 18-07-2024 | AI28: 16-07-2024 | AJ28: DONE | AK28: 16-07-2024 | AM28: 29-07-2024
A29: 28 | B29: 37085 | C29: HLC-B | D29: STB6K0259HLCD | E29: Lallaguda | F29: SCR | G29: HYD | H29: 43507 | J29: Nashik | K29: M-U7D2S04V.005, | L29: Done | M29: UAT2Y440.012 | N29: Done by NW | Q29: Done | R29: Conv-B DONE | T29: Conv-B DONE | U29: Conv-B DONE | AE29: DONE | AF29: 16-07-2024 | AG29: 18-07-2024 | AH29: 18-07-2024 | AI29: 16-07-2024 | AJ29: DONE | AK29: 16-07-2024 | AM29: 29-07-2024
A30: 29 | B30: 37363 | C30: HLC-A | D30: STBDL0742 | E30: Lallaguda | F30: SCR | G30: HYD | H30: 43977 | J30: Nashik | K30: M-U7D2S04V.005, | L30: Done by NW | M30: UAT2Y440.012 | N30: Done by NW | Q30: Done by NW | R30: Done by NW | T30: Conv-A DONE | U30: Conv-A DONE | AE30: DONE | AF30: 15-11-2024 | AG30: 17-08-2024 | AH30: 17-08-2024 | AI30: 17-08-2024 | AJ30: DONE | AK30: 15-11-2024 | AM30: 14-11-2024
A31: 30 | B31: 37363 | C31: HLC-B | D31: STBDL0740HLCD | E31: Lallaguda | F31: SCR | G31: HYD | H31: 43977 | J31: Nashik | K31: M-U7D2S04V.005, | L31: Done by NW | M31: UAT2Y440.012 | N31: Done by NW | Q31: Done by NW | R31: Done by NW | T31: Conv-B DONE | U31: Conv-B DONE | AE31: DONE | AF31: 15-11-2024 | AG31: 17-08-2024 | AH31: 17-08-2024 | AI31: 17-08-2024 | AJ31: DONE | AK31: 15-11-2024 | AM31: 14-11-2024
A32: 31 | B32: 37375 | C32: HLC-A | D32: STBNL0711HLCD | E32: Lallaguda | F32: SCR | G32: HYD | H32: 44004 | J32: Nashik | K32: M-U7D2S04V.005, | L32: Done by NW | M32: UAT2Y440.012 | N32: Done by NW | Q32: Done by NW | R32: Done by NW | T32: Conv-A DONE | U32: Conv-A DONE | AE32: DONE | AF32: 45452 | AG32: 45482 | AH32: 45482 | AI32: 45452 | AJ32: DONE | AK32: 45452 | AM32: 45452
A33: 32 | B33: 37375 | C33: HLC-B | D33: STB7L0608HLCD | E33: Lallaguda | F33: SCR | G33: HYD | H33: 44004 | J33: Nashik | K33: M-U7D2S04V.005, | L33: Done by NW | M33: UAT2Y440.012 | N33: Done by NW | O33: 44075 | Q33: Done by NW | R33: Done by NW | S33: Conv-A DONE | T33: Conv-B DONE | U33: Conv-B DONE | AE33: DONE | AF33: 45452 | AG33: 45482 | AH33: 45482 | AI33: 45452 | AJ33: DONE | AK33: 45452 | AM33: 45452
A34: 33 | B34: 37376 | C34: HLC-A | D34: STBNL0716HLCD | E34: Lallaguda | F34: SCR | G34: HYD | H34: 44006 | J34: Nashik | K34: M-U7D2S04V.005, | L34: Done by NW | M34: UAT2Y440.012 | N34: Done by NW | Q34: Done by NW | R34: Done by NW | T34: Conv-A DONE | U34: Conv-A DONE | AD34: Done | AE34: DONE | AF34: 45633 | AG34: 29-06-2024 | AH34: 29-06-2024 | AI34: 29-06-2024 | AJ34: DONE | AK34: 45450
A35: 34 | B35: 37376 | C35: HLC-B | D35: STB7L0595 | E35: Lallaguda | F35: SCR | G35: HYD | H35: 44006 | J35: Nashik | K35: M-U7D2S04V.005, | L35: Done by NW | M35: UAT2Y440.012 | N35: Done by NW | Q35: Done by NW | R35: Done by NW | T35: Conv-B DONE | U35: Conv-B DONE | AD35: Done | AE35: DONE | AF35: 45633 | AG35: 29-06-2024 | AH35: 29-06-2024 | AI35: 29-06-2024 | AJ35: DONE | AK35: 45450
A36: 35 | B36: 37473 | C36: HLC-A | D36: STB8M0910HLCD | E36: Lallaguda | F36: SCR | G36: HYD | H36: 44153 | J36: Nashik | K36: M-U7D2S04V.005, | L36: Done by NW | M36: UAT2Y440.012 | N36: Done by NW | Q36: Done by NW | R36: Done by NW | S36: Conv-A DONE | T36: Conv-A DONE | U36: Conv-A DONE | X36: Done by NW | AD36: Done | AE36: DONE | AF36: 16-09-2024 | AG36: 24-07-2024 | AH36: 24-07-2024 | AI36: 25-08-2024 | AJ36: DONE | AK36: 25-08-2024 | AM36: 16-09-2024
A37: 36 | B37: 37473 | C37: HLC-B | D37: STB8M0911HLCD | E37: Lallaguda | F37: SCR | G37: HYD | H37: 44153 | J37: Nashik | K37: M-U7D2S04V.005, | L37: Done by NW | M37: UAT2Y440.012 | N37: Done by NW | Q37: Done by NW | R37: Done by NW | S37: Conv-B DONE | T37: Conv-B DONE | U37: Conv-B DONE | X37: Done by NW | AD37: Done | AE37: DONE | AF37: 16-09-2024 | AG37: 24-07-2024 | AH37: 24-07-2024 | AI37: 25-08-2024 | AJ37: DONE | AK37: 25-08-2024 | AM37: 16-09-2024
A38: 37 | B38: 37477 | C38: HLC-A | D38: STB8M0959HLCD | E38: Lallaguda | F38: SCR | G38: HYD | H38: 44157 | J38: Nashik | K38: M-U7D2S04V.005, | L38: Done by NW | M38: UAT2Y440.012 | N38: Done by NW | Q38: Done by NW | R38: Done by NW | T38: Conv-A DONE | U38: Conv-A DONE | X38: Done by NW | AD38: Done | AE38: DONE | AF38: 15-07-2024 | AG38: 23-06-2024 | AH38: 23-06-2024 | AI38: 21-06-2024 | AJ38: DONE | AK38: 22-06-2024 | AM38: 27-12-2024
A39: 38 | B39: 37477 | C39: HLC-B | D39: STB8M0958HLCD | E39: Lallaguda | F39: SCR | G39: HYD | H39: 44157 | J39: Nashik | K39: M-U7D2S04V.005, | L39: Done by NW | M39: UAT2Y440.012 | N39: Done by NW | Q39: Done by NW | R39: Done by NW | T39: Conv-B DONE | U39: Conv-B DONE | X39: Done by NW | AD39: Done | AE39: DONE | AF39: 15-07-2024 | AG39: 23-06-2024 | AH39: 23-06-2024 | AI39: 21-06-2024 | AJ39: DONE | AK39: 22-06-2024 | AM39: 27-12-2024
A40: 39 | B40: 37538 | C40: HLC-A | D40: STB8M0928HLCD | E40: Lallaguda | F40: SCR | G40: HYD | H40: 44226 | J40: Nashik | K40: M-U7D2S04V.005, | L40: Done by NW | M40: UAT2Y440.012 | N40: Done by NW | Q40: Done by NW | R40: Done by NW | T40: Conv-A DONE | U40: Conv-A DONE | X40: Done by NW | AE40: DONE | AF40: 45574 | AG40: 15-06-2024 | AH40: 15-06-2024 | AI40: 45605 | AJ40: DONE | AK40: 45574 | AM40: 45605
...

Sheet Hyderabad Summary
A1: Loco no. | B1: (All)
A3: Row Labels | B3: Total Panel | C3: Software version in Conv | D3: Software version of Text display | E3: Removal of metal short link from M9000 with wire | F3: Replacement of 10 amp fuse with 20 amp | G3: Shifting of wires on O/P contactor | H3: External earth fault wire | I3: Shifting of wire of output voltage available lamp | J3: Sealing of cable entry of panel | K3: Sealing of main fan plate (On which DC-DC converter installed) | L3: Input choke change | M3: Control fuse 6.5amp to 15amp | N3: Display button | O3: DC link bus bar supporter | P3: Count of New Software version (UAT2Y44O.012) of display updation *DATE* | Q3: Count of Sine Filter Capacitor washer fitment and tightness of connection *DATE* | R3: Count of Software version in Conv (200622) (Master) Y6U2N04V.006 (Module) Y6U2N240.005 *DATE* | S3: Count of Heat Sink Cleaning *Date* | T3: Count of I/P contactor SILICON washer | U3: Count of Steel mesh on cyclonic filter on looc wall
A4: BZA | B4: 44 | C4: 17 | D4: 17 | E4: 32 | F4: 32 | H4: 32 | I4: 32 | K4: 1 | L4: 4 | M4: 12 | N4: 22 | O4: 18 | P4: 44 | Q4: 44 | R4: 44 | S4: 32 | T4: 2 | U4: 32
A5: Lallaguda | B5: 128 | C5: 33 | D5: 33 | E5: 64 | F5: 64 | G5: 3 | H5: 64 | I5: 64 | L5: 6 | M5: 50 | N5: 122 | O5: 108 | P5: 122 | Q5: 122 | R5: 122 | S5: 76 | U5: 84
A6: (blank)
A7: Grand Total | B7: 172 | C7: 50 | D7: 50 | E7: 96 | F7: 96 | G7: 3 | H7: 96 | I7: 96 | K7: 1 | L7: 10 | M7: 62 | N7: 144 | O7: 126 | P7: 166 | Q7: 166 | R7: 166 | S7: 108 | T7: 2 | U7: 116

Sheet Detail2
A1: Details for Count of Software version in Conv (200622) (Master) Y6U2N04V.006 (Module) Y6U2N240.005 *DATE* - Base Shed: Raipuram
A3: S.No. | B3: Loco no. | C3: HLC | D3: Serial no. of HLC | E3: Base Shed | F3: Railway | G3: Region | H3: DOC | I3: serial no. | J3: Type of Text display | K3: Software version in Conv | L3: Software version in Conv (Master) U7D2S04V.005 (Module) U7F2S240.005 *DATE* | M3: Software version of display | N3: Software version (UAT2Y44O.012) of display updation *DATE* | O3: Filter clean *DATE* | P3: Filter Change *DATE* | Q3: Removal of metal shortlink from M9000 with wire | R3: Replacement of 10 amp fuse with 20amp | S3: Shifting of wires on O/P contactor | T3: External earth fault wire modification | U3: Shifting of wires of output voltage available lamp | V3: Sealing of cable entry of panel | W3: Sealing of main fan plate (On which DC-DC converter installed) | X3: Mounting of 110 volt DC fan on PWR | Y3: Air leakage status in duct at the back of the converter | Z3: FG block removal from bottom of input choke | AA3: Surge arrestor fitment | AB3: Input choke change (mention sr.no. of new choke_ | AC3: O/P choke change (mention sr.no. of new choke_ | AD3: Control fuse 6.5amp to 15amp (Glass fuse) | AE3: Display button | AF3: DC link bus bar supporter | AG3: Software version in Conv (200622) (Master) Y6U2N04V.006 (Module) Y6U2N240.005 *DATE* | AH3: New Software version (UAT2Y44O.012) of display updation *DATE* | AI3: Sine Filter Capacitor washer fitment and tightness of connection *DATE* | AJ3: ELR setting to check (1amp /10 sec) | AK3: Heat Sink Cleaning *Date* | AL3: I/P contactor SILICON washer | AM3: Steel mesh on cyclonic filter on looc wall
A4: 83 | B4: 30597 | C4: HLC-A | D4: STB6J0110HLCD | E4: Raipuram | F4: SR | G4: CHE | H4: 43053 | I4: 110 | J4: Nashik | K4: M-U7D2S04V.005, MO-U7F2S240.005 | L4: 44335 | M4: UAT2Y440.012 | N4: 44464 | O4: 45310 | R4: Conv-A DONE | T4: Conv-A DONE | Z4: Conv-A DONE | AD4: Conv-A DONE | AF4: Conv-A DONE | AG4: 45464 | AH4: Done | AI4: 45209 | AJ4: Done
A5: 84 | B5: 30597 | C5: HLC-B | D5: STB6J0113HLCD | E5: Raipuram | F5: SR | G5: CHE | H5: 43053 | I5: 113 | J5: Nashik | K5: M-U7D2S04V.005, MO-U7F2S240.005 | L5: 44335 | M5: UAT2Y440.012 | N5: 44464 | O5: 45310 | R5: Conv-B DONE | T5: Conv-B DONE | Z5: Conv-B DONE | AD5: Conv-B DONE | AF5: Conv-B DONE | AG5: 45464 | AH5: Done | AI5: 45209 | AJ5: Done
A6: 91 | B6: 37069 | C6: HLC-A | D6: STB6K0254HLCD | E6: Raipuram | F6: SR | G6: CHE | H6: 43461 | I6: 254 | J6: Nashik | K6: M-U7D2S04V.005, MO-U7F2S240.005 | L6: 44270 | M6: UAT2Y440.012 | N6: 44270 | O6: 45286 | P6: 45049 | R6: Conv-A DONE | T6: Conv-A DONE | U6: Conv-A DONE | Y6: Conv-A DONE | Z6: Conv-A DONE | AD6: Conv-A DONE | AF6: Conv-A DONE | AG6: 45465 | AH6: Done | AI6: 45194 | AJ6: Done
A7: 92 | B7: 37069 | C7: HLC-B | D7: STB7K0264HLCD | E7: Raipuram | F7: SR | G7: CHE | H7: 43461 | I7: 264 | J7: Nashik | K7: M-U7D2S04V.005, MO-U7F2S240.005 | L7: 44270 | M7: UAT2Y440.012 | N7: 44270 | O7: 45286 | P7: 45049 | R7: Conv-B DONE | T7: Conv-B DONE | U7: Conv-B DONE | Y7: Conv-B DONE | Z7: Conv-B DONE | AD7: Conv-B DONE | AF7: Conv-B DONE | AG7: 45465 | AH7: Done | AI7: 45194 | AJ7: Done
A8: 99 | B8: 37203 | C8: HLC-A | D8: STB5L0496HLCD | E8: Raipuram | F8: SR | G8: CHE | H8: 43638 | I8: 496 | J8: Nashik | K8: M-U7D2S04V.005, MO-U7F2S240.005 | L8: 44291 | M8: UAT2Y440.012 | N8: 44196 | O8: 45309 | R8: Conv-A DONE | T8: Conv-A DONE | U8: Conv-A DONE | Y8: Conv-A DONE | Z8: Conv-A DONE | AD8: Conv-A DONE | AF8: Conv-A DONE | AG8: 45465 | AH8: Done | AI8: 45211 | AJ8: Done
A9: 100 | B9: 37203 | C9: HLC-B | D9: STB4L0471HLCD | E9: Raipuram | F9: SR | G9: CHE | H9: 43638 | I9: 471 | J9: Nashik | K9: M-U7D2S04V.005, MO-U7F2S240.005 | L9: 44291 | M9: UAT2Y440.012 | N9: 44196 | O9: 45309 | R9: Conv-B DONE | T9: Conv-B DONE | U9: Conv-B DONE | Y9: Conv-B DONE | Z9: Conv-B DONE | AD9: Conv-B DONE | AG9: 45465 | AH9: Done | AI9: 45211 | AJ9: Done
A10: 105 | B10: 37208 | C10: HLC-A | D10: STB5L0499HLCD | E10: Raipuram | F10: SR | G10: CHE | H10: 43641 | I10: 499 | J10: Nashik | K10: M-U7D2S04V.005, MO-U7F2S240.005 | L10: 44250 | M10: UAT2Y440.012 | N10: 44188 | O10: 45114 | R10: Conv-A DONE | T10: Conv-A DONE | U10: Conv-A DONE | Y10: Conv-A DONE | Z10: Conv-A DONE | AD10: Conv-A DONE | AF10: Conv-A DONE | AG10: 45465 | AI10: 45206 | AJ10: Done | AM10: 45467
A11: 106 | B11: 37208 | C11: HLC-B | D11: STB5L0519HLCD | E11: Raipuram | F11: SR | G11: CHE | H11: 43641 | I11: 519 | J11: Nashik | K11: M-U7D2S04V.005, MO-U7F2S240.005 | L11: Done | M11: UAT2Y440.012 | N11: 44375 | O11: 45114 | Q11: Done by NW | R11: Conv-B DONE | T11: Conv-B DONE | Y11: Conv-B DONE | Z11: Conv-B DONE | AD11: Conv-B DONE | AF11: Conv-B DONE | AG11: 45465 | AI11: 45206 | AJ11: Done | AM11: 45467
A12: 124 | B12: 39082 | C12: HLC-B | D12: STB4L0486HLCD | E12: Raipuram | F12: SR | G12: CHE | H12: 43686 | I12: 486 | J12: Nashik | K12: M-U7D2S04V.005, MO-U7F2S240.005 | L12: 44246 | M12: UAT2Y440.012 | N12: 44199 | R12: Conv-B DONE | T12: Conv-B DONE | U12: Conv-B DONE | Z12: Conv-B DONE | AD12: Conv-B DONE | AF12: Conv-B DONE | AG12: 45468 | AI12: 45168 | AJ12: Done
A13: 123 | B13: 39082 | C13: HLC-A | D13: STB4L0488HLCD | E13: Raipuram | F13: SR | G13: CHE | H13: 43686 | I13: 488 | J13: Nashik | K13: M-U7D2S04V.005, MO-U7F2S240.005 | L13: 44246 | M13: UAT2Y440.012 | N13: 44199 | R13: Conv-A DONE | T13: Conv-A DONE | U13: Conv-A DONE | Z13: Conv-A DONE | AB13: EL19J04040 | AD13: Conv-A DONE | AF13: Conv-A DONE | AG13: 45468 | AI13: 45168 | AJ13: Done
B14: 30410 | C14: HLC-B | D14: STB9P1345HLCD | E14: Raipuram | F14: SR | G14: CHE | H14: 45300 | I14: 1345 | J14: Nashik | M14: Done by NW | N14: Done by NW | O14: Done by NW | P14: Done by NW | Q14: Done by NW | T14: Done by NW | V14: Done by NW | Z14: Done by NW | AB14: Done by NW | AE14: 45300 | AF14: 1amp/10 sec | AG14: 45469 | AJ14: Done
A15: 196 | B15: 30410 | C15: HLC-A | D15: STB9P1356HLCD | E15: Raipuram | F15: SR | G15: CHE | H15: 45300 | I15: 1356 | J15: Nashik | M15: Done by NW | N15: Done by NW | O15: Done by NW | P15: Done by NW | Q15: Done by NW | T15: Done by NW | V15: Done by NW | Z15: Done by NW | AB15: Done by NW | AE15: 45300 | AF15: 1amp/10 sec | AG15: 45469 | AJ15: Done
B16: 30367 | C16: HLC-B | D16: STBDP1386HLCD | E16: Raipuram | F16: SR | G16: CHE | H16: 45005 | I16: 1386 | J16: Nashik | O16: 45289 | Q16: Done by NW | R16: Done by NW | S16: Done by NW | T16: Done by NW | U16: Done by NW | X16: Done by NW | Z16: Done by NW | AD16: Done by NW | AF16: Done by NW | AG16: 45469 | AI16: 45196 | AJ16: Done
A17: 181 | B17: 30367 | C17: HLC-A | D17: STBDP1388HLCD | E17: Raipuram | F17: SR | G17: CHE | H17: 45005 | I17: 1388 | J17: Nashik | O17: 45289 | Q17: Done by NW | R17: Done by NW | S17: Done by NW | T17: Done by NW | U17: Done by NW | X17: Done by NW | Z17: Done by NW | AD17: Done by NW | AF17: Done by NW | AG17: 45469 | AI17: 45196 | AJ17: Done
A18: 146 | B18: 30350 | C18: HLC-B | D18: STB4N1118HLCD | E18: Raipuram | F18: SR | G18: CHE | I18: 1118 | J18: Nashik | K18: M-U7D2S04V.005, MO-U7F2S240.005 | L18: Done by NW | M18: UAT2Y440.012 | N18: Done by NW | O18: 45289 | Q18: Done by NW | R18: Done by NW | S18: Done by NW | T18: Conv-B DONE | U18: Conv-B DONE | X18: Done by NW | Y18: Conv-B DONE | Z18: Conv-B DONE | AD18: Conv-B DONE | AF18: Conv-B DONE | AG18: 45469 | AH18: Done | AI18: 45198 | AJ18: Done | AM18: 45463
A19: 145 | B19: 30350 | C19: HLC-A | D19: STB4N1120HLCD | E19: Raipuram | F19: SR | G19: CHE | I19: 1120 | J19: Nashik | K19: M-U7D2S04V.005, MO-U7F2S240.005 | L19: Done by NW | M19: UAT2Y440.012 | N19: Done by NW | O19: 45289 | Q19: Done by NW | R19: Done by NW | S19: Done by NW | T19: Conv-A DONE | U19: Conv-A DONE | X19: Done by NW | Y19: Conv-A DONE | Z19: Conv-A DONE | AD19: Conv-A DONE | AF19: Conv-A DONE | AG19: 45469 | AH19: Done | AI19: 45198 | AJ19: Done | AM19: 45463
A20: 128 | B20: 39121 | C20: HLC-B | D20: STBOL0675HLCD | E20: Raipuram | F20: SR | G20: CHE | H20: 43840 | I20: 675 | J20: Nashik | K20: M-U7D2S04V.005, MO-U7F2S240.005 | L20: 44551 | M20: UAT2Y440.012 | N20: 44643 | O20: 45072 | Q20: Done by NW | R20: Done by NW | T20: Conv-B DONE | U20: Conv-B DONE | W20: Conv-B DONE | Z20: Conv-B DONE | AD20: Conv-B DONE | AF20: Conv-B DONE | AG20: 45469
A21: 127 | B21: 39121 | C21: HLC-A | D21: STBOL0670HLCD | E21: Raipuram | F21: SR | G21: CHE | H21: 43840 | I21: 670 | J21: Nashik | K21: M-U7D2S04V.005, MO-U7F2S240.005 | L21: 44551 | M21: UAT2Y440.012 | N21: 44549 | O21: 45072 | Q21: Done by NW | R21: Done by NW | T21: Conv-A DONE | U21: Conv-A DONE | W21: Conv-A DONE | Z21: Conv-A DONE | AD21: Conv-A DONE | AF21: Conv-A DONE | AG21: 45469
A22: 136 | B22: 37581 | C22: HLC-A | D22: STBDL0757HLCD | E22: Raipuram | F22: SR | G22: CHE | H22: 44334 | I22: 757 | J22: Nashik | K22: M-U7D2S04V.005, MO-U7F2S240.005 | L22: Done | M22: UAT2Y440.012 | N22: Done by NW | O22: 45145 | Q22: Done by NW | R22: Done by NW | T22: Conv-B DONE | U22: Conv-B DONE | Z22: Conv-B DONE | AD22: Conv-B DONE | AG22: 45470 | AH22: Done | AI22: 45232 | AJ22: Done
A23: 135 | B23: 37581 | C23: HLC-B | D23: STBDL0755HLCD | E23: Raipuram | F23: SR | G23: CHE | H23: 44334 | I23: 755 | J23: Nashik | K23: M-U7D2S04V.005, MO-U7F2S240.005 | L23: Done | M23: UAT2Y440.012 | N23: Done by NW | O23: 45145 | Q23: Done by NW | R23: Done by NW | T23: Conv-A DONE | U23: Conv-A DONE | Z23: Conv-A DONE | AD23: Conv-A DONE | AG23: 45470 | AH23: Done | AI23: 45232 | AJ23: Done
A24: 71 | B24: 30475 | C24: HLC-A | D24: STBDF0047HLCA | E24: Raipuram | F24: SR | G24: CHE | H24: 42511 | I24: 47 | J24: Imported | K24: M-U7D2S04V.005, MO-U7F2S240.005 | L24: 44168 | M24: L3I2ZY72.008 | N24: Done | O24: 45281 | R24: Conv-A DONE | T24: Conv-A DONE | Y24: Conv-A DONE | Z24: Conv-A DONE | AD24: Conv-A DONE | AG24: 45470 | AH24: Done | AI24: 45192 | AJ24: Done
A25: 72 | B25: 30475 | C25: HLC-B | D25: STBDF0048HLCA | E25: Raipuram | F25: SR | G25: CHE | H25: 42511 | I25: 48 | J25: Imported | K25: M-U7D2S04V.005, MO-U7F2S240.005 | L25: 44168 | M25: L3I2ZY72.008 | N25: Done | O25: 45281 | R25: Conv-B DONE | T25: Conv-B DONE | Y25: Conv-B DONE | Z25: Conv-B DONE | AD25: Conv-B DONE | AG25: 45470 | AH25: Done | AI25: 45192 | AJ25: Done
A26: 81 | B26: 30545 | C26: HLC-A | D26: STB9H0083HLCC | E26: Raipuram | F26: SR | G26: CHE | H26: 42886 | I26: 83 | J26: Imported | K26: M-U7D2S04V.005, MO-U7F2S240.005 | L26: 44176 | M26: UAT2Y440.012 | N26: 44196 | O26: 45286 | P26: 44663 | R26: Conv-A DONE | T26: Conv-A DONE | Y26: Conv-A DONE | Z26: Conv-A DONE | AD26: Conv-A DONE | AG26: 45470 | AH26: Done | AI26: 45192 | AJ26: Done
A27: 82 | B27: 30545 | C27: HLC-B | D27: STB9H0082HLCC | E27: Raipuram | F27: SR | G27: CHE | H27: 42886 | I27: 82 | J27: Imported | K27: M-U7D2S04V.005, MO-U7F2S240.005 | L27: 44176 | M27: UAT2Y440.012 | N27: 44196 | O27: 45286 | P27: 44663 | R27: Conv-B DONE | T27: Conv-B DONE | Y27: Conv-B DONE | Z27: Conv-B DONE | AD27: Conv-B DONE | AG27: 45470 | AH27: Done | AI27: 45192 | AJ27: Done
A28: 95 | B28: 37143 | C28: HLC-A | D28: STB2L0413HLCD | E28: Raipuram | F28: SR | G28: CHE | H28: 43571 | I28: 413 | J28: Nashik | K28: M-U7D2S04V.005, MO-U7F2S240.005 | L28: 44180 | M28: UAT2Y440.012 | N28: 44180 | O28: 45148 | R28: Conv-A DONE | T28: Conv-A DONE | U28: Conv-A DONE | Y28: Conv-A DONE | Z28: Conv-A DONE | AB28: EL18K02045-R | AD28: Conv-A DONE | AF28: Conv-A DONE | AG28: 45470 | AH28: Done | AI28: 45215 | AJ28: Done
A29: 96 | B29: 37143 | C29: HLC-B | D29: STB2L0412HLCD | E29: Raipuram | F29: SR | G29: CHE | H29: 43571 | I29: 412 | J29: Nashik | K29: M-U7D2S04V.005, MO-U7F2S240.005 | L29: 44180 | M29: UAT2Y440.012 | N29: 44180 | O29: 45148 | Q29: Con-B done | R29: Conv-B DONE | T29: Conv-B DONE | U29: Conv-B DONE | Y29: Conv-B DONE | Z29: Conv-B DONE | AD29: Conv-B DONE | AF29: Conv-B DONE | AG29: 45470 | AH29: Done | AI29: 45215 | AJ29: Done
B30: 30390 | C30: HLC-B | D30: STBDP1384HLCD | E30: Raipuram | F30: SR | G30: CHE | H30: 45216 | I30: 1384 | J30: Nashik | Q30: Done by NW | R30: Done by NW | S30: Done by NW | T30: Done by NW | U30: Done by NW | X30: Done by NW | AD30: Done by NW | AF30: Done by NW | AG30: 45471 | AJ30: Done
A31: 194 | B31: 30390 | C31: HLC-A | D31: STBDP1387HLCD | E31: Raipuram | F31: SR | G31: CHE | H31: 45216 | I31: 1387 | J31: Nashik | Q31: Done by NW | R31: Done by NW | S31: Done by NW | T31: Done by NW | U31: Done by NW | X31: Done by NW | AD31: Done by NW | AF31: Done by NW | AG31: 45471 | AJ31: Done
A32: 122 | B32: 39081 | C32: HLC-B | D32: STB4L0480HLCD | E32: Raipuram | F32: SR | G32: CHE | H32: 43691 | I32: 480 | J32: Nashik | K32: M-U7D2S04V.005, MO-U7F2S240.005 | L32: 44161 | M32: UAT2Y440.012 | N32: 44182 | O32: 45080 | R32: Conv-B DONE | T32: Conv-B DONE | U32: Conv-B DONE | Y32: Conv-B DONE | Z32: Conv-B DONE | AD32: Conv-B DONE | AF32: Conv-B DONE | AG32: 45471 | AI32: 45268 | AJ32: 1amp/10 sec
A33: 121 | B33: 39081 | C33: HLC-A | D33: STB4L0485HLCD | E33: Raipuram | F33: SR | G33: CHE | H33: 43691 | I33: 485 | J33: Nashik | K33: M-U7D2S04V.005, MO-U7F2S240.005 | L33: 44161 | M33: UAT2Y440.012 | N33: 44182 | O33: 45080 | R33: Conv-A DONE | T33: Conv-A DONE | U33: Conv-A DONE | Y33: Conv-A DONE | Z33: Conv-A DONE | AD33: Conv-A DONE | AF33: Conv-A DONE | AG33: 45471 | AI33: 45268 | AJ33: 1amp/10 sec
A34: 111 | B34: 37213 | C34: HLC-A | D34: STB5L0509HLCD | E34: Raipuram | F34: SR | G34: CHE | H34: 43670 | I34: 509 | J34: Nashik | K34: M-U7D2S04V.005, MO-U7F2S240.005 | L34: 44255 | M34: UAT2Y440.012 | N34: 44199 | O34: 45310 | Q34: Done by NW | R34: Conv-A DONE | T34: Conv-A DONE | U34: Conv-A DONE | Z34: Conv-A DONE | AD34: Conv-A DONE | AF34: Conv-A DONE | AG34: 45471 | AI34: 45134 | AJ34: Done
A35: 112 | B35: 37213 | C35: HLC-B | D35: STB4L0492HLCD | E35: Raipuram | F35: SR | G35: CHE | H35: 43670 | I35: 492 | J35: Nashik | K35: M-U7D2S04V.005, MO-U7F2S240.005 | L35: 44255 | M35: UAT2Y440.012 | N35: 44199 | O35: 45310 | R35: Conv-B DONE | T35: Conv-B DONE | U35: Conv-B DONE | Z35: Conv-B DONE | AD35: Conv-B DONE | AF35: Conv-B DONE | AG35: 45471 | AI35: 45134 | AJ35: Done
A36: 115 | B36: 37514 | C36: HLC-A | D36: STB8M0925HLCD | E36: Raipuram | F36: SR | G36: CHE | H36: 44195 | I36: 925 | J36: Nashik | K36: M-U7D2S04V.005, MO-U7F2S240.005 | L36: Done by NW | M36: UAT2Y440.012 | N36: 44346 | Q36: Done by NW | R36: Done by NW | T36: Conv-A DONE | U36: Conv-A DONE | X36: Done by NW | Z36: Conv-A DONE | AD36: Conv-A DONE | AF36: Conv-A DONE | AG36: 45472 | AI36: 45227 | AJ36: Done
A37: 116 | B37: 37514 | C37: HLC-B | D37: STBDL0759HLCD | E37: Raipuram | F37: SR | G37: CHE | H37: 44195 | I37: 759 | J37: Nashik | K37: M-U7D2S04V.005, MO-U7F2S240.005 | L37: 44327 | M37: UAT2Y440.012 | N37: 44346 | Q37: Done by NW | R37: Done by NW | T37: Conv-B DONE | U37: Conv-B DONE | X37: Done by NW | Z37: Conv-B DONE | AD37: Conv-B DONE | AF37: Conv-B DONE | AG37: 45472 | AI37: 45227 | AJ37: Done
B38: 30392 | C38: HLC-B | D38: STBDN1180HLCD | E38: Raipuram | F38: SR | G38: CHE | H38: 45110 | I38: 1180 | J38: Nashik | M38: Done by NW | N38: Done by NW | Q38: Done by NW | R38: Done by NW | S38: Done by NW | T38: Done by NW | U38: Done by NW | X38: Done by NW | Z38: Done by NW | AD38: Done by NW | AF38: Done by NW | AG38: 45474 | AI38: 45204 | AJ38: Done
A39: 187 | B39: 30392 | C39: HLC-A | D39: STBOP1361HLCD | E39: Raipuram | F39: SR | G39: CHE | H39: 45110 | I39: 1361 | J39: Nashik | M39: Done by NW | N39: Done by NW | Q39: Done by NW | R39: Done by NW | S39: Done by NW | T39: Done by NW | U39: Done by NW | X39: Done by NW | Z39: Done by NW | AD39: Done by NW | AF39: Done by NW | AG39: 45474 | AI39: 45204 | AJ39: Done
