Workbook

Sheet WH Stock Mastersheet
B1: Material Receipt Details | N1: =SUBTOTAL(9,N3:N1048576) -> 173694 | O1: =SUBTOTAL(9,O3:O1048576) -> 13208 | P1: =SUBTOTAL(9,P3:P1048576) -> 24149 | Q1: =+N1-P1 -> 149545
A2: Project Name | B2: Sr. No. | C2: Date of receipt | D2: Material Receipt From | E2: Warehouse Doc. No & Vendor Document No. | F2: Warehouse Documents Date / Vendor Doc. Date | G2: LR No/ Date | H2: Vendor Place | I2: P.O. No. | J2: SAP Code | K2: Part Code | L2: Description | M2: UOM | N2: Received Qty | O2: Qty. Verified | P2: Dispatched Qty | Q2: Balance Qty | R2: VNS Item Location | S2: Box No / Bin No | T2: Customer Invoice / Challan No | U2: Date | V2: Dispatch Date | W2: Customer Name | X2: Location | Y2: Order By | Z2: Docket No | AA2: Transporter / Courier Name | AB2: Project | AC2: Customer P.O. No | AD2: WBS | AE2: Remark if Any
B3: 1 | C3: 44637 | D3: Delhi Sahabad Warehouse | E3: SMO/0002 | F3: 44634 | H3: DELHI | J3: 109687772 | K3: 109687772 | L3: DISPLAY (FRAM )MOUNTING BRACKET | M3: Nos | N3: 20 | Q3: =+N3-P3 -> 20 | R3: Near Gate No 3 | S3: W. Box No 34 (1 To 5)
B4: 2 | C4: 44637 | D4: Delhi Sahabad Warehouse | E4: SMO/0001 | F4: 44634 | H4: DELHI | K4: HN350 ( DH350/HK351N)6 | L4: BATTERY CHARGER ASSEMBLY DRG NO 4TRS-231 | M4: Nos | N4: 8 | Q4: =+N4-P4 -> 8 | R4: Near Gate No 3 | S4: W. Box No 35
B5: 3 | C5: 44643 | D5: Delhi Sahabad Warehouse SHUBHADA POLYMERS PRODUCTS PVT LTD | E5: SMO/0004 SHS201001538 | F5: 17-03-2022 13-01-20 | G5: 359972307 GATIKWE | H5: MUMBAI | I5: 4509462642 | J5: 102316360 | K5: ECC1/ECC2 S3 | L5: CABLE PENETRATION 800A ECC1/ECC2 S3 | M5: Nos | N5: 24 | Q5: =+N5-P5 -> 24 | R5: Rack No 25 | S5: Box No 25 & 26
B6: 4 | C6: 44643 | D6: Delhi Sahabad Warehouse SHUBHADA POLYMERS PRODUCTS PVT LTD | E6: SMO/0004 SHS201001538 | F6: 17-03-2022 13-01-20 | G6: 359972307 GATIKWE | H6: MUMBAI | I6: 4509462642 | J6: A5E47174092 | K6: A5E436723831_AD | L6: CABLE PENETRATION 600-650A | M6: Nos | N6: 24 | Q6: =+N6-P6 -> 24 | R6: Rack No 29 | S6: Box No 27 & 28
A7: WAG9/6k | B7: 5 | C7: 44643 | D7: Delhi Sahabad Warehouse HARTING INDIA LTD. | E7: SMO/0004 3600059304 | F7: 17-03-2022 31-12-20 | G7: XPRESSBEES,91691183107 31-12-20 | H7: chennai | I7: 4509978514 | J7: 112136075 | K7: 09300240581 | L7: HARTING Hood Female HAN 24B-GS-ZV-29 '09300240581 | M7: Nos | N7: 54 | P7: 10 | Q7: =+N7-P7 -> 44 | R7: Rack No 6/D1 | S7: Box No 29 | T7: UP/DC/FY22/00065 | U7: 44707 | V7: 44707 | W7: SIEMENS LTD. G. HOUSE | X7: Paschim Burdwan WB | Y7: Mr. Arka Dey | Z7: 218110400 | AA7: SPOTON/DELHIVERY | AB7: WAG9/6k | AC7: 70201134101308 | AD7: 62OP 30878
A8: WAG9/6k | B8: 5 | D8: Delhi Sahabad Warehouse HARTING INDIA LTD. | J8: 112136075 | K8: 09300240581 | L8: HARTING Hood Female HAN 24B-GS-ZV-29 '09300240581 | M8: Nos | P8: 6 | Q8: =+Q7-P8 -> 38 | R8: Rack No 6/D1 | S8: Box No 29 | T8: UP/DC/FY22/00078 | U8: 44711 | V8: 44711 | W8: DDU Shed Mugal Sarai | X8: VARANASI | Y8: Mr. Arka Dey | Z8: BY HAND | AA8: Mr. Saurabh Mishra | AB8: WAG9/6k | AE8: Material for BLW Commissioning against 49x CLW
A9: WAG9/6k | B9: 5 | D9: Delhi Sahabad Warehouse HARTING INDIA LTD. | J9: 112136075 | K9: 09300240581 | L9: HARTING Hood Female HAN 24B-GS-ZV-29 '09300240581 | M9: Nos | P9: 4 | Q9: =+Q8-P9 -> 34 | R9: Rack No 6/D1 | S9: Box No 29 | T9: UP/DC/FY22/00079 | U9: 44712 | V9: 44712 | W9: SD II Stores Depot 2 PLW | X9: Patiala | Y9: Mr. Arka Dey | Z9: 215973860 | AA9: SPOTON/DELHIVERY | AB9: WAG9/6k | AC9: 20212095100413 | AD9: 62OP 30878
A10: WAG9/6k | B10: 5 | D10: Delhi Sahabad Warehouse HARTING INDIA LTD. | J10: 112136075 | K10: 09300240581 | L10: HARTING Hood Female HAN 24B-GS-ZV-29 '09300240581 | M10: Nos | P10: 6 | Q10: =+Q9-P10 -> 28 | R10: Rack No 6/D1 | S10: Box No 29 | T10: UP/DC/FY22/00090 | U10: 44714 | V10: 44714 | W10: SD II Stores Depot 2 PLW | X10: Patiala | Y10: Mr. Arka Dey | Z10: 216001993 | AA10: DELHIVERY LTD | AB10: WAG9/6k | AC10: 20212095100413 | AD10: 62OP 30878
A11: WAG9/6k | B11: 5 | D11: Delhi Sahabad Warehouse HARTING INDIA LTD. | J11: 112136075 | K11: 09300240581 | L11: HARTING Hood Female HAN 24B-GS-ZV-29 '09300240581 | M11: Nos | P11: 4 | Q11: =+Q10-P11 -> 24 | R11: Rack No 6/D1 | S11: Box No 29 | T11: UP/DC/FY22/00089 | U11: 44714 | V11: 44714 | W11: SR DEE ELECTRIC LOCO SHED | X11: TUGHALAKABAD DELHI | Y11: Mr. Arka Dey | Z11: 216001992 | AA11: DELHIVERY LTD | AB11: WAG9/6k | AC11: 29215006D00977 | AD11: 62OP 30878
A12: WAG9/6k | B12: 5 | D12: Delhi Sahabad Warehouse HARTING INDIA LTD. | J12: 112136075 | K12: 09300240581 | L12: HARTING Hood Female HAN 24B-GS-ZV-29 '09300240581 | M12: Nos | P12: 4 | Q12: =+Q11-P12 -> 20 | R12: Rack No 6/D1 | S12: Box No 29 | T12: UP/DC/FY22/00128 | U12: 44734 | V12: 44734 | W12: CEE/D&D/CLW/CRJ | X12: CHITTARANJAN WB | Y12: MR. ARKA DEY | Z12: 215973560 | AA12: DELHIVERY LTD | AB12: WAG9/6k | AC12: 70201134101308 | AD12: 62OP 30878
B13: 6 | C13: 44643 | D13: Delhi Sahabad Warehouse WEIDMULLER ELECTRONIC INDIA PVT LTD | E13: SMO/0004 203001 | F13: 17-03-2022 25-11-19 | G13: 1004427023 26-11-19 Rivigo Service Pvt.Ltd. | H13: BENGALURU | I13: 4509411596 | J13: 109710324 | K13: WFF185/AH 600V 360 AMP | L13: FEED THROUGH TERMINAL BLOCK WFF 185/AH 1029600000 | M13: Nos | N13: 36 | Q13: =+N13-P13 -> 36 | R13: Rack No 2 /F1 & 2 | S13: Box No 30 & 31
B14: 7 | C14: 44643 | D14: Delhi Sahabad Warehouse TDK COMPONENTS PTE LTD | E14: SMO/0004 56738710 | F14: 17-03-2022 24-12-21 | G14: MANJEET TRANSPORT / 10923 | H14: SINGAPORE | I14: 4200899863 | J14: 109443666 | K14: B32373A4257J 80 | L14: MET FILM CAPACITOR RoHS COMPATIBLE 250uF +-5% 480V PEC MKD AC | M14: Nos | N14: 19 | Q14: =+N14-P14 -> 19 | R14: Rack No 6/E | S14: Box No 24
B15: 8 | C15: 44643 | D15: Delhi Sahabad Warehouse Span HI tech Pvt. Ltd. | E15: SMO/0004 337 | F15: 17-03-2022 03-02-21 | G15: 123315152 03-02-21 GATI KWE | H15: NASIK | I15: 4510318862 | J15: 110320774 | K15: 1902MA1001_A | L15: HEP CUBICLE FOR WAP7 DRG NO 1902MA1001_A (GASKET) | M15: MTR | N15: 94 | Q15: =+N15-P15 -> 94 | R15: Rack No 6/C | S15: Box 18
B16: 9 | C16: 44643 | D16: Delhi Sahabad Warehouse | E16: SMO/0015 | F16: 44646 | H16: DELHI | J16: 107983770 | K16: 7210N-181 | L16: INSTRUMENT COOLING FAN. 7210N-181 /Churning Fan | M16: Nos | N16: 25 | Q16: =+N16-P16 -> 25 | R16: Rack No 27 | S16: Box No 19,20,21
B17: 10 | C17: 44643 | D17: Delhi Sahabad Warehouse SIEMENS AG | E17: SM0/0003 7411RF3800333725 | F17: 16-03-2022 10-12-20 | G17: MANJEET TRANSPORT / 8359, 04-03-21 | H17: GERMANY | I17: 4200791659 | J17: 101999218 | K17: XL KF i (A2B00075622) | L17: SITET® XL KF i (A2B00075622) | M17: Nos | N17: 36 | P17: 2 | Q17: =+N17-P17 -> 34 | R17: Rack No 6/A,B,C | S17: Box No 32 (32/1 to 32/36) | T17: UP/DC/FY22/00064 | U17: 44706 | V17: 44706 | W17: SR DEE ELECTRIC LOCO SHED | X17: TUGHALAKABAD DELHI | Y17: Mr. Arka Dey | Z17: 218110392 | AA17: SPOTON LOGISTIC Pvt. Ltd. | AB17: 9000HP Locomotive | AE17: Mitigate loco failure
B18: 10 | D18: Delhi Sahabad Warehouse SIEMENS AG | J18: 101999218 | K18: XL KF i (A2B00075622) | L18: SITET® XL KF i (A2B00075622) | M18: Nos | P18: 30 | Q18: =+Q17-P18 -> 4 | R18: Rack No 6/A,B,C | S18: Box No 32 (32/1 to 32/36) | T18: UP/DC/FY22/00076 | U18: 44711 | V18: 44712 | W18: Siemens Ltd- Nasik Work | X18: NASIK | Y18: Mr. Arka Dey | Z18: 215973859 | AA18: SPOTON LOGISTIC Pvt. Ltd. | AE18: Item sent for inspection
B19: 10 | D19: Delhi Sahabad Warehouse SIEMENS AG | J19: 101999218 | K19: XL KF i (A2B00075622) | L19: SITET® XL KF i (A2B00075622) | M19: Nos | P19: 4 | Q19: =+Q18-P19 -> 0 | R19: Rack No 6/A,B,C | S19: Box No 32 (32/1 to 32/36) | T19: UP/DC/FY22/00079 | U19: 44712 | V19: 44712 | W19: SD II Stores Depot 2 PLW | X19: Patiala | Y19: Mr. Arka Dey | Z19: 215973860 | AA19: SPOTON LOGISTIC Pvt. Ltd. | AB19: WAG9/6k | AC19: 20212095100413 | AD19: 62OP 30878
B20: 11 | C20: 44645 | D20: Delhi Sahabad Warehouse Norish Automation GMBH | E20: SM0/0007 2022116 | F20: 19-03-2022 13-02-20 | G20: MANJEET TRANSPORT/ 5799 26-02-20 | H20: GERMANY | I20: 4200754583 | J20: 107123964 | K20: FAHZ5-P3-024/028/007 | L20: SPEED SENSOR NORIS | M20: Nos | N20: =93+47+8+32+8+42 -> 230 | P20: 70 | Q20: =+N20-P20 -> 160 | R20: Rack No 31,32,35,36 | S20: Box No 13,9,11,10,12 | T20: UP/DC/FY22/00046 | U20: 44690 | V20: 44694 | W20: Siemens ltd Jodhpur Site | X20: Bhagat Ki kothi Jodhpur | Y20: Mr. Arka Dey | Z20: 223951853 | AA20: Spoton | AB20: DE loco AMC | AC20: NA | AD20: 62OP-30781.P.02 | AE20: Faulty Batch Replacement from Noris And Transport and Packaging Debits to the CS
B21: 12 | C21: 44645 | D21: Delhi Sahabad Warehouse | E21: SM0/0007 | F21: 44639 | J21: 107123967 | K21: GT46MAC-T | L21: TEMP. SENSOR GT46MAC-T | M21: Nos | N21: 38 | Q21: =+N21-P21 -> 38 | R21: Rack No 31 | S21: Box No 13 & 14
B22: 13 | C22: 44645 | D22: Delhi Sahabad Warehouse | E22: SM0/0007 | F22: 44639 | J22: 101668554 | K22: A5E00747920 | L22: MAIN BOARD 6FH9543-3BY60 A5E00747920 | M22: Nos | N22: 3 | Q22: =+N22-P22 -> 3 | R22: Rack No 31 | S22: Box No 14
A23: WAG9/6k | B23: 14 | C23: 44645 | D23: Delhi Sahabad Warehouse HARTING INDIA LTD. | E23: SMO/0008 3600076242 | F23: 21-03-2022 28-02-2022 | G23: 4532/ 10-03-2022 Paul Service | H23: chennai | I23: 4511059519 | J23: 109492181 | K23: 09670003476 | L23: HARTING D SUB -S- FEMALE-18-22 CRIMP CONDUCT P.N. 09670003476 | M23: Nos | N23: 1000 | P23: 460 | Q23: =+N23-P23 -> 540 | R23: Rack No 2/ D2 | S23: Box No 15 | T23: UP/DC/FY22/00022 | U23: 44672 | V23: 44674 | W23: TEKNOCRATS CONTROL PVT. LTD. | X23: NASIK | Y23: Mr. Arka Dey | Z23: 50815918834 | AA23: BLUE DART SARFACE | AB23: WAG9/6k | AC23: 70201134101308 | AD23: 62OP 30878 | AE23: Short supply material dispatched now
A24: WAG9/6k | B24: 14 | D24: Delhi Sahabad Warehouse HARTING INDIA LTD. | J24: 109492181 | K24: 09670003476 | L24: HARTING D SUB -S- FEMALE-18-22 CRIMP CONDUCT P.N. 09670003476 | M24: Nos | P24: 50 | Q24: =+Q23-P24 -> 490 | R24: Rack No 2/ D2 | S24: Box No 15 | T24: UP/DC/FY22/00040 | U24: 44685 | V24: 44685 | W24: Siemens / Guest house | X24: Paschim Burdwan WB | Y24: Mr. Arka Dey | Z24: BY HAND | AA24: Mr. Saurabh Mishra | AB24: 6000HP: CLW PO 6k49x | AC24: 70201134101308 | AD24: 62OP 30878 | AE24: Short supply material dispatched now
A25: WAG9/6k | B25: 14 | D25: Delhi Sahabad Warehouse HARTING INDIA LTD. | J25: 109492181 | K25: 09670003476 | L25: HARTING D SUB -S- FEMALE-18-22 CRIMP CONDUCT P.N. 09670003476 | M25: Nos | P25: 160 | Q25: =+Q24-P25 -> 330 | R25: Rack No 2/ D2 | S25: Box No 15 | T25: UP/DC/FY22/00065 | U25: 44707 | V25: 44707 | W25: SIEMENS LTD. G. HOUSE | X25: Paschim Burdwan WB | Y25: Mr. Arka Dey | Z25: 218110400 | AA25: SPOTON/DELHIVERY | AB25: WAG9/6k | AC25: 70201134101308 | AD25: 62OP 30878
A26: WAG9/6k | B26: 14 | D26: Delhi Sahabad Warehouse HARTING INDIA LTD. | J26: 109492181 | K26: 09670003476 | L26: HARTING D SUB -S- FEMALE-18-22 CRIMP CONDUCT P.N. 09670003476 | M26: Nos | P26: 64 | Q26: =+Q25-P26 -> 266 | R26: Rack No 2/ D2 | S26: Box No 15 | T26: UP/DC/FY22/00079 | U26: 44712 | V26: 44712 | W26: SD II Stores Depot 2 PLW | X26: Patiala | Y26: Mr. Arka Dey | Z26: 215973860 | AA26: SPOTON/DELHIVERY | AB26: WAG9/6k | AC26: 20212095100413 | AD26: 62OP 30878
A27: WAG9/6k | B27: 14 | D27: Delhi Sahabad Warehouse HARTING INDIA LTD. | J27: 109492181 | K27: 09670003476 | L27: HARTING D SUB -S- FEMALE-18-22 CRIMP CONDUCT P.N. 09670003476 | M27: Nos | P27: 96 | Q27: =+Q26-P27 -> 170 | R27: Rack No 2/ D2 | S27: Box No 15 | T27: UP/DC/FY22/00090 | U27: 44714 | V27: 44714 | W27: SD II Stores Depot 2 PLW | X27: Patiala | Y27: Mr. Arka Dey | Z27: 216001993 | AA27: DELHIVERY LTD | AB27: WAG9/6k | AC27: 20212095100413 | AD27: 62OP 30878
A28: WAG9/6k | B28: 14 | D28: Delhi Sahabad Warehouse HARTING INDIA LTD. | J28: 109492181 | K28: 09670003476 | L28: HARTING D SUB -S- FEMALE-18-22 CRIMP CONDUCT P.N. 09670003476 | M28: Nos | P28: 64 | Q28: =+Q27-P28 -> 106 | R28: Rack No 2/ D2 | S28: Box No 15 | T28: UP/DC/FY22/00089 | U28: 44714 | V28: 44714 | W28: SR DEE ELECTRIC LOCO SHED | X28: TUGHALAKABAD DELHI | Y28: Mr. Arka Dey | Z28: 216001992 | AA28: DELHIVERY LTD | AB28: WAG9/6k | AC28: 29215006D00977 | AD28: 62OP 30878
A29: WAG9/6k | B29: 14 | D29: Delhi Sahabad Warehouse HARTING INDIA LTD. | J29: 109492181 | K29: 09670003476 | L29: HARTING D SUB -S- FEMALE-18-22 CRIMP CONDUCT P.N. 09670003476 | M29: Nos | P29: 64 | Q29: =+Q28-P29 -> 42 | R29: Rack No 2/ D2 | S29: Box No 15 | T29: UP/DC/FY22/00128 | U29: 44734 | V29: 44734 | W29: CEE/D&D/CLW/CRJ | X29: CHITTARANJAN WB | Y29: MR. ARKA DEY | Z29: 215973560 | AA29: DELHIVERY LTD | AB29: WAG9/6k | AC29: 70201134101308 | AD29: 62OP 30878
A30: WAG9/6k | B30: 15 | C30: 44645 | D30: Delhi Sahabad Warehouse HARTING INDIA LTD. | E30: SMO/0008 3600076242 | F30: 21-03-2022 28-02-2022 | G30: 4532/PAUL SERVICE | H30: CHENNAI | I30: 4511059519 | J30: 109609630 | K30: 09150006123 | L30: HARTING R15-STI-C (AU) 0.5-AWG20 09150006123 | M30: Nos | N30: 200 | P30: 48 | Q30: =+N30-P30 -> 152 | R30: Rack No 2 /D2 | S30: Box No 15 | T30: UP/DC/FY22/00040 | U30: 44685 | V30: 44685 | W30: Siemens / Guest house | X30: Paschim Burdwan WB | Y30: Mr. Arka Dey | Z30: BY HAND | AA30: Mr. Saurabh Mishra | AB30: 6000HP: CLW PO 6k49x | AC30: 70201134101308 | AD30: 62OP 30878 | AE30: Short supply material dispatched now
A31: WAG9/6k | B31: 15 | D31: Delhi Sahabad Warehouse HARTING INDIA LTD. | I31: 4511059519 | J31: 109609630 | K31: 09150006123 | L31: HARTING R15-STI-C (AU) 0.5-AWG20 09150006123 | M31: Nos | P31: 80 | Q31: =+Q30-P31 -> 72 | R31: Rack No 2 /D2 | S31: Box No 15 | T31: UP/DC/FY22/00065 | U31: 44707 | V31: 44707 | W31: SIEMENS LTD. G. HOUSE | X31: Paschim Burdwan WB | Y31: Mr. Arka Dey | Z31: 218110400 | AA31: SPOTON/DELHIVERY | AB31: WAG9/6k | AC31: 70201134101308 | AD31: 62OP 30878
A32: WAG9/6k | B32: 15 | D32: Delhi Sahabad Warehouse HARTING INDIA LTD. | J32: 109609630 | K32: 09150006123 | L32: HARTING R15-STI-C (AU) 0.5-AWG20 09150006123 | M32: Nos | P32: 48 | Q32: =+Q31-P32 -> 24 | R32: Rack No 2 /D2 | S32: Box No 15 | T32: UP/DC/FY22/00078 | U32: 44711 | V32: 44711 | W32: DDU Shed Mugal Sarai | X32: VARANASI | Y32: Mr. Arka Dey | Z32: BY HAND | AA32: Mr. Saurabh Mishra | AB32: WAG9/6k | AE32: Material for BLW Commissioning against 49x CLW
A33: WAG9/6k | B33: 15 | D33: Delhi Sahabad Warehouse HARTING INDIA LTD. | J33: 109609630 | K33: 09150006123 | L33: HARTING R15-STI-C (AU) 0.5-AWG20 09150006123 | M33: Nos | P33: 24 | Q33: =+Q32-P33 -> 0 | R33: Rack No 2 /D2 | S33: Box No 15 | T33: UP/DC/FY22/00079 | U33: 44712 | V33: 44712 | W33: SD II Stores Depot 2 PLW | X33: Patiala | Y33: Mr. Arka Dey | Z33: 215973860 | AA33: SPOTON/DELHIVERY | AB33: WAG9/6k | AC33: 20212095100413 | AD33: 62OP 30878
A34: WAG9/6k | B34: 16 | C34: 44645 | D34: Delhi Sahabad Warehouse HARTING INDIA LTD. | E34: SMO/0008 3600076242 | F34: 44641 | G34: 4532/PAUL SERVICE | H34: chennai | I34: 4511059519 | J34: 109492197 | K34: 61030000067 | L34: CRIMP FLANGE FOR D-SUB HARTING (S102117360) FORMVB CONNECTOR 61030000067 | M34: Nos | N34: 600 | P34: 80 | Q34: =+N34-P34 -> 520 | R34: Rack No 2 /D2 | S34: Box No 15 | T34: UP/DC/FY22/00065 | U34: 44707 | V34: 44707 | W34: SIEMENS LTD. G. HOUSE | X34: Paschim Burdwan WB | Y34: Mr. Arka Dey | Z34: 218110400 | AA34: SPOTON/DELHIVERY | AB34: WAG9/6k | AC34: 70201134101308 | AD34: 62OP 30878
A35: WAG9/6k | B35: 16 | D35: Delhi Sahabad Warehouse HARTING INDIA LTD. | J35: 109492197 | K35: 61030000067 | L35: CRIMP FLANGE FOR D-SUB HARTING (S102117360) FORMVB CONNECTOR 61030000067 | M35: Nos | P35: 14 | Q35: =+Q34-P35 -> 506 | R35: Rack No 2 /D2 | S35: Box No 15 | T35: UP/DC/FY22/00079 | U35: 44712 | V35: 44712 | W35: SD II Stores Depot 2 PLW | X35: Patiala | Y35: Mr. Arka Dey | Z35: 215973860 | AA35: SPOTON/DELHIVERY | AB35: WAG9/6k | AC35: 20212095100413 | AD35: 62OP 30878
A36: WAG9/6k | B36: 16 | D36: Delhi Sahabad Warehouse HARTING INDIA LTD. | J36: 109492197 | K36: 61030000067 | L36: CRIMP FLANGE FOR D-SUB HARTING (S102117360) FORMVB CONNECTOR 61030000067 | M36: Nos | P36: 48 | Q36: =+Q35-P36 -> 458 | R36: Rack No 2 /D2 | S36: Box No 15 | T36: UP/DC/FY22/00090 | U36: 44714 | V36: 44714 | W36: SD II Stores Depot 2 PLW | X36: Patiala | Y36: Mr. Arka Dey | Z36: 216001993 | AA36: DELHIVERY LTD | AB36: WAG9/6k | AC36: 20212095100413 | AD36: 62OP 30878
A37: WAG9/6k | B37: 16 | D37: Delhi Sahabad Warehouse HARTING INDIA LTD. | J37: 109492197 | K37: 61030000067 | L37: CRIMP FLANGE FOR D-SUB HARTING (S102117360) FORMVB CONNECTOR 61030000067 | M37: Nos | P37: 32 | Q37: =+Q36-P37 -> 426 | R37: Rack No 2 /D2 | S37: Box No 15 | T37: UP/DC/FY22/00089 | U37: 44714 | V37: 44714 | W37: SR DEE ELECTRIC LOCO SHED | X37: TUGHALAKABAD DELHI | Y37: Mr. Arka Dey | Z37: 216001992 | AA37: DELHIVERY LTD | AB37: WAG9/6k | AC37: 29215006D00977 | AD37: 62OP 30878
A38: WAG9/6k | B38: 16 | D38: Delhi Sahabad Warehouse HARTING INDIA LTD. | J38: 109492197 | K38: 61030000067 | L38: CRIMP FLANGE FOR D-SUB HARTING (S102117360) FORMVB CONNECTOR 61030000067 | M38: Nos | P38: 32 | Q38: =+Q37-P38 -> 394 | R38: Rack No 46 | S38: Box No 16 | T38: UP/DC/FY22/00128 | U38: 44734 | V38: 44734 | W38: CEE/D&D/CLW/CRJ | X38: CHITTARANJAN WB | Y38: MR. ARKA DEY | Z38: 215973560 | AA38: DELHIVERY LTD | AB38: WAG9/6k | AC38: 70201134101308 | AD38: 62OP 30878
A39: WAG9/6k | B39: 17 | C39: 44645 | D39: Delhi Sahabad Warehouse HARTING INDIA LTD. | E39: SMO/0008 3600076242 | F39: 21-03-2022 20-02-2022 | G39: 4532/10-03-22 Paul Service | H39: CHENNAI | I39: 4511059519 | J39: 109492194 | K39: 61030012010 | L39: HARTING INDU COM 9P 1T ENTRY HEX SCREW 4-40 P.N. 61030012010 | M39: Nos | N39: 470 | P39: 30 | Q39: =+N39-P39 -> 440 | R39: Rack 2/E1 & E2 | S39: Box No 16 & 17 | T39: UP/DC/FY22/00022 | U39: 44672 | V39: 44674 | W39: TEKNOCRATS CONTROL PVT. LTD. | X39: NASIK | Y39: Mr. Arka Dey | Z39: 50815918834 | AA39: BLUE DART SARFACE | AB39: WAG9/6k | AC39: 70201134101308 | AD39: 62OP 30878 | AE39: Short supply material dispatched now
A40: WAG9/6k | B40: 17 | D40: Delhi Sahabad Warehouse HARTING INDIA LTD. | J40: 109492194 | K40: 61030012010 | L40: HARTING INDU COM 9P 1T ENTRY HEX SCREW 4-40 P.N. 61030012010 | M40: Nos | P40: 80 | Q40: =+Q39-P40 -> 360 | R40: Rack 2/E1 & E2 | S40: Box No 16 & 17 | T40: UP/DC/FY22/00065 | U40: 44707 | V40: 44707 | W40: SIEMENS LTD. G. HOUSE | X40: Paschim Burdwan WB | Y40: Mr. Arka Dey | Z40: 218110400 | AA40: SPOTON/DELHIVERY | AB40: WAG9/6k | AC40: 70201134101308 | AD40: 62OP 30878
...

Sheet In-ward Register
N1: =M1-M2 -> -1157585.4 | O1: =O2/10000000 -> 0.28611668
B2: Material In-ward register as on 31 -July-25 | M2: =SUM(M4:M1048576) -> 1157585.4 | O2: =SUBTOTAL(9,O3:O1735) -> 2861166.8 | Q2: 55
A3: Sr. No. | B3: Date of receipt | C3: Material Receipt From | D3: Warehouse Doc. No & Vendor Document No. | E3: Warehouse Documents Date / Vendor Doc. Date | F3: LR No/ Date | G3: Vendor Place | H3: PO. No. | I3: Sap Code | J3: Part Code | K3: Description | L3: UOM | M3: Received Qty | N3: Unit Price as per P.o. | O3: Total Value Of Receipt | P3: Remarks
A4: 1 | B4: 44637 | C4: Delhi Sahabad Warehouse Integra Engineering India Ltd. | D4: SMO/0002 | E4: 44634 | G4: DELHI | H4: 4509249408 | I4: 109687772 | J4: 109687772 | K4: DISPLAY (FRAM )MOUNTING BRACKET | L4: Nos | M4: 20 | N4: 911 | O4: =M4*N4 -> 18220
A5: 2 | B5: 44637 | C5: Delhi Sahabad Warehouse Hind Rectifiers Ltd. | D5: SMO/0001 | E5: 44634 | G5: DELHI | H5: 4508422862 | I5: 108227130 | J5: HN350 ( DH350/HK351N)6 | K5: BATTERY CHARGER ASSEMBLY DRG NO 4TRS-231 rectifier with Blocker Diodes and Current Limiting Resistors for WDx4 Diesel Locomotive” | L5: Nos | M5: 8 | N5: 42000 | O5: =M5*N5 -> 336000
A6: 3 | B6: 44643 | C6: Delhi Sahabad Warehouse SHUBHADA POLYMERS PRODUCTS PVT LTD | D6: SMO/0004 SHS201001538 | E6: 17-03-2022 13-01-20 | F6: 359972307 GATIKWE | G6: MUMBAI | H6: 4509462642 | I6: 102316360 | J6: ECC1/ECC2 S3 | K6: CABLE PENETRATION 800A ECC1/ECC2 S3 | L6: Nos | M6: 24 | N6: 1141 | O6: =M6*N6 -> 27384
A7: 4 | B7: 44643 | C7: Delhi Sahabad Warehouse SHUBHADA POLYMERS PRODUCTS PVT LTD | D7: SMO/0004 SHS201001538 | E7: 17-03-2022 13-01-20 | F7: 359972307 GATIKWE | G7: MUMBAI | H7: 4509462642 | I7: A5E47174092 | J7: A5E436723831_AD | K7: CABLE PENETRATION 600-650A | L7: Nos | M7: 24 | N7: 953 | O7: =M7*N7 -> 22872
A8: 5 | B8: 44643 | C8: Delhi Sahabad Warehouse HARTING INDIA LTD. | D8: SMO/0004 3600059304 | E8: 17-03-2022 31-12-20 | F8: XPRESSBEES,91691183107 31-12-20 | G8: chennai | H8: 4509978514 | I8: 112136075 | J8: 09300240581 | K8: HARTING Hood Female HAN 24B-GS-ZV-29 '09300240581 | L8: Nos | M8: 54 | N8: 1196.19 | O8: =M8*N8 -> 64594.26
A9: 6 | B9: 44643 | C9: Delhi Sahabad Warehouse WEIDMULLER ELECTRONIC INDIA PVT LTD | D9: SMO/0004 203001 | E9: 17-03-2022 25-11-19 | F9: 1004427023 26-11-19 Rivigo Service Pvt.Ltd. | G9: BENGALURU | H9: 4509411596 | I9: 109710324 | J9: WFF185/AH 600V 360 AMP | K9: FEED THROUGH TERMINAL BLOCK WFF 185/AH 1029600000 | L9: Nos | M9: 36 | N9: 74 | O9: =M9*N9 -> 2664
A10: 7 | B10: 44643 | C10: Delhi Sahabad Warehouse TDK COMPONENTS PTE LTD | D10: SMO/0004 56738710 | E10: 17-03-2022 24-12-21 | F10: MANJEET TRANSPORT / 10923 | G10: SINGAPORE | H10: 4200899863 | I10: 109443666 | J10: B32373A4257J 80 | K10: MET FILM CAPACITOR RoHS COMPATIBLE 250uF +-5% 480V PEC MKD AC | L10: Nos | M10: 19 | N10: 4222.16 | O10: =M10*N10 -> 80221.04
A11: 8 | B11: 44643 | C11: Delhi Sahabad Warehouse Span HI tech Pvt. Ltd. | D11: SMO/0004 337 | E11: 17-03-2022 03-02-21 | F11: 123315152 03-02-21 GATI KWE | G11: NASIK | H11: 4510318862 | I11: 110320774 | J11: 1902MA1001_A | K11: HEP CUBICLE FOR WAP7 DRG NO 1902MA1001_A (GASKET) | L11: Mtr. | M11: 94 | N11: 295 | O11: =M11*N11 -> 27730
A12: 9 | B12: 44643 | C12: Delhi Sahabad Warehouse Ebm-Papst India Pvt. Ltd. | D12: SMO/0015 | E12: 44646 | G12: DELHI | H12: 4508872517 | I12: 107146625 | J12: 7210N-181 | K12: INSTRUMENT COOLING FAN. 7210N-181 /Churning Fan | L12: Nos | M12: 25 | N12: 4954 | O12: =M12*N12 -> 123850
A13: 10 | B13: 44643 | C13: Delhi Sahabad Warehouse SIEMENS AG | D13: SM0/0003 7411RF3800333725 | E13: 16-03-2022 10-12-20 | F13: MANJEET TRANSPORT / 8359, 04-03-21 | G13: GERMANY | H13: 4200791659 | I13: 101999218 | J13: XL KF i (A2B00075622) | K13: A2B00075622 DRIVER'S DESK TERMINAL SITET XL KF 1 74V | L13: Nos | M13: 36 | N13: 239925.69 | O13: =M13*N13 -> 8637324.8
A14: 11 | B14: 44645 | C14: Delhi Sahabad Warehouse Norish Automation GMBH | D14: SM0/0007 2022116 | E14: 19-03-2022 13-02-20 | F14: MANJEET TRANSPORT/ 5799 26-02-20 | G14: GERMANY | H14: 4200754583 | I14: 107123964 | J14: FAHZ5-P3-024/028/007 | K14: SPEED SENSOR NORIS | L14: Nos | M14: 230 | N14: 9467.32 | O14: =M14*N14 -> 2177483.6
A15: 12 | B15: 44645 | C15: Delhi Sahabad Warehouse Oasis Instruments Company | D15: SM0/0007 | E15: 44639 | G15: Hyderabad | H15: 4507585177 | I15: 107123967 | J15: GT46MAC-T | K15: TEMP. SENSOR GT46MAC-T | L15: Nos | M15: 38 | N15: 11000 | O15: =M15*N15 -> 418000
A16: 13 | B16: 44645 | C16: Delhi Sahabad Warehouse P6230A607 | D16: SM0/0007 | E16: 44639 | H16: 4505739651 | I16: 101668554 | J16: A5E00747920 | K16: MAIN BOARD 6FH9543-3BY60 A5E00747920, S101638370 | L16: Nos | M16: 3 | N16: 0 | O16: =M16*N16 -> 0
A17: 14 | B17: 44645 | C17: Delhi Sahabad Warehouse HARTING INDIA LTD. | D17: SMO/0008 3600076242 | E17: 21-03-2022 28-02-2022 | F17: 4532/ 10-03-2022 Paul Service | G17: chennai | H17: 4511059519 | I17: 109492181 | J17: 09670003476 | K17: HARTING D SUB -S- FEMALE-18-22 CRIMP CONDUCT P.N. 09670003476 | L17: Nos | M17: 1000 | N17: 18.35 | O17: =M17*N17 -> 18350
A18: 15 | B18: 44645 | C18: Delhi Sahabad Warehouse HARTING INDIA LTD. | D18: SMO/0008 3600076242 | E18: 21-03-2022 28-02-2022 | F18: 4532/PAUL SERVICE | G18: CHENNAI | H18: 4511059519 | I18: 109609630 | J18: 09150006123 | K18: HARTING R15-STI-C (AU) 0.5-AWG20 09150006123 | L18: Nos | M18: 200 | N18: 19.26 | O18: =M18*N18 -> 3852
A19: 16 | B19: 44645 | C19: Delhi Sahabad Warehouse HARTING INDIA LTD. | D19: SMO/0008 3600076242 | E19: 44641 | F19: 4532/PAUL SERVICE | G19: chennai | H19: 4511059519 | I19: 109492197 | J19: 61030000067 | K19: CRIMP FLANGE FOR D-SUB HARTING (S102117360) FORMVB CONNECTOR 61030000067 | L19: Nos | M19: 600 | N19: 66.92 | O19: =M19*N19 -> 40152
A20: 17 | B20: 44645 | C20: Delhi Sahabad Warehouse HARTING INDIA LTD. | D20: SMO/0008 3600076242 | E20: 21-03-2022 20-02-2022 | F20: 4532/10-03-22 Paul Service | G20: CHENNAI | H20: 4511059519 | I20: 109492194 | J20: 61030012010 | K20: HARTING INDU COM 9P 1T ENTRY HEX SCREW 4-40 P.N. 61030012010 | L20: Nos | M20: 470 | N20: 234.9 | O20: =M20*N20 -> 110403
A21: 18 | B21: 44645 | C21: Delhi Sahabad Warehouse HARTING INDIA LTD. | D21: SMO/0008 3600076242 | E21: 21-03-2022 28-02-2022 | F21: 4532/PAUL SERVICE | G21: CHENNAI | H21: 4511059519 | I21: 109609632 | J21: 09150043013 | K21: HAN 4 QUINTAX STIFT, 3-9.5MM 09150043013 | L21: Nos | M21: 60 | N21: 100.06 | O21: =M21*N21 -> 6003.6
A22: 19 | B22: 44645 | C22: Delhi Sahabad Warehouse HARTING INDIA LTD. | D22: SMO/0008 3600076242 | E22: 21-03-2022 28-02-2022 | F22: 4532/ 10-03-22 Paul Service | G22: Chennai | H22: 4511059519 | I22: 109492180 | J22: 09670094701 | K22: D- SUB CRIMP 9-POLE FEMALE ASSEMBLY '09670094701 | L22: Nos | M22: 600 | N22: 32.22 | O22: =M22*N22 -> 19332
A23: 20 | B23: 44645 | C23: Delhi Sahabad Warehouse SIEMENS LTD | D23: SMO/0005 MH1927751244 MH1927751265 | E23: 18-03-2022 11-09-19 16-09-19 | F23: X32953068/26-11-19 DTDC COURIER | G23: BHIWANDI | H23: 4509192857 | I23: 108140376 | J23: 3RT1076-6XF46-0LA2 | K23: CONTACTOR 3RT1076-6XF46-0LA2 | L23: Nos | M23: 18 | N23: 29845 | O23: =M23*N23 -> 537210
A24: 21 | B24: 44648 | C24: Delhi Sahabad Warehouse Ebm-Papst India Pvt. Ltd. | D24: SMO/0011 | E24: 44644 | G24: DELHI | H24: 4508872517 | I24: 107146625 | J24: 7210N-181 | K24: INSTRUMENT COOLING FAN. 7210N-181 /Churning Fan | L24: Nos | M24: 100 | N24: 4954 | O24: =M24*N24 -> 495400
A25: 22 | B25: 44648 | C25: Delhi Sahabad Warehouse LEROY | D25: SMO/0011 FE410009 | E25: 24-03-2022 25-02-21 | G25: FRANCE | H25: 4200826011 | I25: 111381215 | J25: BRIO R114 | K25: MODULE BRIO R114 MAKE LEROY-AUTOMATION | L25: Nos | M25: 4 | N25: 79877 | O25: =M25*N25 -> 319508
A26: 23 | B26: 44648 | C26: Delhi Sahabad Warehouse LEROY | D26: SMO/0011 FE410009 | E26: 24-03-2022 25-02-21 | G26: FRANCE | H26: 4200826011 | I26: 111381216 | J26: PTOLBPX118 | K26: MODULE PTOLBPX118 MAKE LEROY-AUTOMATION | L26: Nos | M26: 6 | N26: 4438 | O26: =M26*N26 -> 26628
A27: 24 | B27: 44648 | C27: Delhi Sahabad Warehouse LEROY | D27: SMO/10001 FE410009 | E27: 22-03-2022 25-02-21 | G27: FRANCE | H27: 4200826011 | I27: 111381214 | J27: RIOM T51321 | K27: MODULE RIOM T51321 MAKE LEROY-AUTOMATION | L27: Nos | M27: 1 | N27: 97627 | O27: =M27*N27 -> 97627
A28: 25 | B28: 44648 | C28: Delhi Sahabad Warehouse SVAN ANALYTICAL INSTRUMENT PVT LTD. | D28: SMO/0011 3081/21-22 | E28: 24-03-2022 27-04-2021 | G28: DOMBILLI MH | H28: 4510395452 | I28: 111391860 | J28: 111391860 | K28: Micro volume Viscometer-OIL APPLICATION | L28: Set | M28: 1 | N28: 375000 | O28: =M28*N28 -> 375000
A29: 26 | B29: 44648 | C29: Delhi Sahabad Warehouse Siemens Ltd-Nashik Works | D29: SMO/0006 | E29: 44637 | G29: DELHI | H29: 4510365470 | I29: 101668585 | J29: EDPM4610 | K29: S101091363 GASKET GISTA SECTION EDPM4610 | L29: Mtr. | M29: 50 | N29: 415 | O29: =M29*N29 -> 20750
A30: 27 | B30: 44648 | C30: Delhi Sahabad Warehouse Spectra Connectronics LLP | D30: SMO/10001 | E30: 44642 | G30: DELHI | H30: 4510927065 | I30: A5E41521351 | J30: 3P_5.8mm | K30: ACC_CONN_HOUSING_FEMALE_3P_5.8mm | L30: Nos | M30: 46 | N30: 10.53 | O30: =M30*N30 -> 484.38
A31: 28 | B31: 44648 | C31: Delhi Sahabad Warehouse Spectra Connectronics LLP | D31: SMO/10001 | E31: 44642 | G31: DELHI | H31: 4508414831 | I31: A5E41521162 | J31: 0.08-0.33mm2_PhBz | K31: ACC_CONN_CONT_FEMALE_0.08-0.33mm2_PhBz | L31: Nos | M31: 48 | N31: 1.17 | O31: =M31*N31 -> 56.16
A32: 29 | B32: 44648 | C32: Delhi Sahabad Warehouse New United Metal & Engineering Work | D32: SMO/10001 | E32: 44642 | G32: DELHI | H32: 4510987455 | I32: A5E46938651 | J32: SN 66355 B30-A | K32: Siemens Name Plate as per SN 66355 B30-A | L32: Nos | M32: 4 | N32: 406 | O32: =M32*N32 -> 1624
A33: 30 | B33: 44648 | C33: Delhi Sahabad Warehouse | D33: SMO/0006 | E33: 44637 | G33: DELHI | I33: 102086056 | J33: 102086056 | K33: HEAT SHRINK TUBE 12.0/6 BLACK | L33: Mtr. | M33: 100 | N33: 8.75 | O33: =M33*N33 -> 875
A34: 31 | B34: 44648 | C34: Delhi Sahabad Warehouse Gala Shrink Fit | D34: SMO/0006 | E34: 44637 | G34: DELHI | H34: 4510385088 | I34: A5E49610997 | J34: A5E49610997 | K34: Heat Shrink Sleeve_30.0/15.0mm Black | L34: Mtr. | M34: 50 | N34: 34 | O34: =M34*N34 -> 1700
A35: 32 | B35: 44648 | C35: Delhi Sahabad Warehouse | D35: SMO/0006 | E35: 44637 | G35: DELHI | H35: 4509771905 | I35: 110408140 | J35: 110408140 | K35: Heat Shrinkable Transperant Tube for 185 SqmmCable | L35: Mtr. | M35: 100 | N35: 40 | O35: =M35*N35 -> 4000
A36: 33 | B36: 44648 | C36: Delhi Sahabad Warehouse JAINSONS INDIA | D36: SMO/0006 0000880/20-21 | E36: 17-03-2022 24-09-20 | G36: NEW DELHI | H36: 4510011036 | I36: 110456652 | J36: 1061000250230 | K36: Heat Shrinkable Transperant Tube 150 Sqmm cable 25/12.5 | L36: Mtr. | M36: 50 | N36: 33 | O36: =M36*N36 -> 1650
A37: 34 | B37: 44648 | C37: Delhi Sahabad Warehouse JAINSONS INDIA | D37: SMO/0006 0000880/20-21 | E37: 17-03-2022 24-09-20 | G37: NEW DELHI | H37: 4510011036 | I37: 110456658 | J37: 110456658 | K37: Heat Shrinkable Transparent tube 35 cabl (12/6) | L37: Mtr. | M37: 100 | N37: 8.75 | O37: =M37*N37 -> 875
A38: 35 | B38: 44648 | C38: Delhi Sahabad Warehouse JAINSONS INDIA | D38: SMO/0006 0000880/20-21 | E38: 17-03-2022 24-09-20 | G38: NEW DELHI | H38: 4510011036 | I38: 110456655 | J38: 110456655 | K38: Heat Shrinkable Transparent tube 50 cabl (14/7 | L38: Mtr. | M38: 100 | N38: 11 | O38: =M38*N38 -> 1100
A39: 36 | B39: 44648 | C39: Delhi Sahabad Warehouse JAINSONS INDIA | D39: SMO/0006 0000880/20-21 | E39: 17-03-2022 24-09-20 | G39: NEW DELHI | H39: 4510011036 | I39: 110408141 | J39: 110408141 | K39: Heat Shrinkable Transperant Tube for 70 Sq.mm Cable HST 18MM Clear | L39: Mtr. | M39: 100 | N39: 19.5 | O39: =M39*N39 -> 1950
A40: 37 | B40: 44648 | C40: Delhi Sahabad Warehouse | D40: SMO/0006 | E40: 44637 | G40: DELHI | I40: B | J40: B | K40: HEP CUBICAL | L40: Box | M40: 2 | N40: 0 | O40: =M40*N40 -> 0
...

Sheet Out-ward Register
F1: Total Disp Qty. | G1: =Summery!H2-'Out-ward Register'!F2 -> 0 | U1: Dispatch Value | V1: Receipt Value | W1: Balance
A2: Material Out-ward register As on 31-July-25 | F2: =SUM(F4:F1048576) -> 604899.94 | U2: =SUBTOTAL(9,U4:U3176) -> 2.3616877e+08 | V2: ='In-ward Register'!O2 -> 2861166.8 | W2: =V2-U2 -> -2.333076e+08
A3: Sr. No. | B3: SAP Code | C3: Part Code | D3: Description | E3: UOM | F3: Dispatched Qty | G3: Customer Invoice / Challan No | H3: Date | I3: Dispatch Date | J3: Customer Name | K3: Location | L3: Order By | M3: Docket No | N3: Transporter / Courier Name | O3: Project | P3: Customer P.O. No | Q3: WBS | R3: Remark if Any | S3: Price As per P.o. | T3: Currency | U3: Dispatch Value
A4: 1 | B4: 109447744 | C4: 803203 | D4: 803203 LION-DO8-24V-110V-LUE LION I/O MODULE DIGITAL OUTPUTS | E4: Nos | F4: 129 | G4: UP/DC/FY22/00018 | H4: 44666 | I4: 44666 | J4: Siemens Ltd- Nasik Work | K4: Nasik | L4: Mr. Arka Dey | M4: 226168328 | N4: SPOTON LOGISTIC Pvt. Ltd. | O4: WAG9/6k | P4: 70201134101308 | Q4: 62OP 30878 | R4: Short supply material dispatched now | S4: 19040 | T4: INR | U4: =S4*F4 -> 2456160
A5: 2 | B5: 109447749 | C5: 803401 | D5: LION Erweiterungsmodul, 4 analoge Ausg. 803401 | E5: Nos | F5: 36 | G5: UP/DC/FY22/00018 | H5: 44666 | I5: 44666 | J5: Siemens Ltd- Nasik Work | K5: Nasik | L5: Mr. Arka Dey | M5: 226168328 | N5: SPOTON LOGISTIC Pvt. Ltd. | O5: WAG9/6k | P5: 70201134101308 | Q5: 62OP 30878 | R5: Short supply material dispatched now | S5: 22525 | T5: INR | U5: =S5*F5 -> 810900
A6: 3 | B6: 109447743 | C6: 803201 | D6: LION Erweiterungsmodul,8 Wechslerkanaele 803201 | E6: Nos | F6: 89 | G6: UP/DC/FY22/00018 | H6: 44666 | I6: 44666 | J6: Siemens Ltd- Nasik Work | K6: Nasik | L6: Mr. Arka Dey | M6: 226168328 | N6: SPOTON LOGISTIC Pvt. Ltd. | O6: WAG9/6k | P6: 70201134101308 | Q6: 62OP 30878 | R6: Short supply material dispatched now | S6: 18615 | T6: INR | U6: =S6*F6 -> 1656735
A7: 4 | B7: 109447737 | C7: 800103 | D7: LION POWER SUPPLY 36 W DC24V/110V 800103 | E7: Nos | F7: 89 | G7: UP/DC/FY22/00018 | H7: 44666 | I7: 44666 | J7: Siemens Ltd- Nasik Work | K7: Nasik | L7: Mr. Arka Dey | M7: 226168328 | N7: SPOTON LOGISTIC Pvt. Ltd. | O7: WAG9/6k | P7: 70201134101308 | Q7: 62OP 30878 | R7: Short supply material dispatched now | S7: 18020 | T7: INR | U7: =S7*F7 -> 1603780
A8: 5 | B8: 109447745 | C8: 803301 | D8: LION-AI4-U-LUE (Analog Input, 4 channels 803301 | E8: Nos | F8: 35 | G8: UP/DC/FY22/00018 | H8: 44666 | I8: 44666 | J8: Siemens Ltd- Nasik Work | K8: Nasik | L8: Mr. Arka Dey | M8: 226168328 | N8: SPOTON LOGISTIC Pvt. Ltd. | O8: WAG9/6k | P8: 70201134101308 | Q8: 62OP 30878 | R8: Short supply material dispatched now | S8: 26265 | T8: INR | U8: =S8*F8 -> 919275
A9: 6 | B9: 109447740 | C9: 803001 | D9: LION-Busskoppler-MVB-LUE 803001 | E9: Nos | F9: 91 | G9: UP/DC/FY22/00018 | H9: 44666 | I9: 44666 | J9: Siemens Ltd- Nasik Work | K9: Nasik | L9: Mr. Arka Dey | M9: 226168328 | N9: SPOTON LOGISTIC Pvt. Ltd. | O9: WAG9/6k | P9: 70201134101308 | Q9: 62OP 30878 | R9: Short supply material dispatched now | S9: 40800 | T9: INR | U9: =S9*F9 -> 3712800
A10: 7 | B10: 109492197 | C10: 61030000067 | D10: CRIMP FLANGE FOR D-SUB HARTING (S102117360) FORMVB CONNECTOR 61030000067 | E10: Nos | F10: 92 | G10: UP/DC/FY22/00022 | H10: 44672 | I10: 44674 | J10: TEKNOCRATS CONTROL PVT. LTD. | K10: NASIK | L10: Mr. Arka Dey | M10: 50815918834 | N10: BLUE DART SARFACE | O10: WAG9/6k | P10: 70201134101308 | Q10: 62OP 30878 | R10: Short supply material dispatched now | S10: 66.92 | T10: INR | U10: =S10*F10 -> 6156.64
A11: 8 | B11: 107146625 | C11: 4318N/2N | D11: Ebm-Papst Churning Fan-Model No- 4318N/2N | E11: Nos | F11: 69 | G11: UP/DC/FY22/00022 | H11: 44672 | I11: 44674 | J11: TEKNOCRATS CONTROL PVT. LTD. | K11: NASIK | L11: Mr. Arka Dey | M11: 50815918834 | N11: BLUE DART SARFACE | O11: WAG9/6k | P11: 70201134101308 | Q11: 62OP 30878 | R11: Short supply material dispatched now | S11: 1516 | T11: INR | U11: =S11*F11 -> 104604
A12: 9 | B12: 109612594 | C12: 279-316 | D12: END AND INTERMEDIATE PLATE 279-316 | E12: Nos | F12: 200 | G12: UP/DC/FY22/00022 | H12: 44672 | I12: 44674 | J12: TEKNOCRATS CONTROL PVT. LTD. | K12: NASIK | L12: Mr. Arka Dey | M12: 50815918834 | N12: BLUE DART SARFACE | O12: WAG9/6k | P12: 70201134101308 | Q12: 62OP 30878 | R12: Short supply material dispatched now | S12: 8.22 | T12: INR | U12: =S12*F12 -> 1644
A13: 10 | B13: 111418258 | C13: 0234002.MXP | D13: FUSE FOR TERMINAL BOARD LITTLE FUSE 234 SERIES, 3A | E13: Nos | F13: 36 | G13: UP/DC/FY22/00022 | H13: 44672 | I13: 44674 | J13: TEKNOCRATS CONTROL PVT. LTD | K13: NASIK | L13: Mr. Arka Dey | M13: 50815918834 | N13: BLUE DART SARFACE | O13: WAG9/6k | P13: 70201134101308 | Q13: 62OP 30878 | R13: Short supply material dispatched now | S13: 28.68 | T13: INR | U13: =S13*F13 -> 1032.48
A14: 11 | B14: 109492181 | C14: 09670003476 | D14: HARTING D SUB -S- FEMALE-18-22 CRIMP CONDUCT P.N. 09670003476 | E14: Nos | F14: 460 | G14: UP/DC/FY22/00022 | H14: 44672 | I14: 44674 | J14: TEKNOCRATS CONTROL PVT. LTD. | K14: NASIK | L14: Mr. Arka Dey | M14: 50815918834 | N14: BLUE DART SARFACE | O14: WAG9/6k | P14: 70201134101308 | Q14: 62OP 30878 | R14: Short supply material dispatched now | S14: 18.35 | T14: INR | U14: =S14*F14 -> 8441
A15: 12 | B15: 109492194 | C15: 61030012010 | D15: HARTING INDU COM 9P 1T ENTRY HEX SCREW 4-40 P.N. 61030012010 | E15: Nos | F15: 30 | G15: UP/DC/FY22/00022 | H15: 44672 | I15: 44674 | J15: TEKNOCRATS CONTROL PVT. LTD. | K15: NASIK | L15: Mr. Arka Dey | M15: 50815918834 | N15: BLUE DART SARFACE | O15: WAG9/6k | P15: 70201134101308 | Q15: 62OP 30878 | R15: Short supply material dispatched now | S15: 234.9 | T15: INR | U15: =S15*F15 -> 7047
A16: 13 | B16: 109492196 | C16: 61030000054 | D16: Harting Inducom Crimp ferrule 9,5- 10,5mm 61030000054 | E16: Nos | F16: 92 | G16: UP/DC/FY22/00022 | H16: 44672 | I16: 44674 | J16: TEKNOCRATS CONTROL PVT. LTD. | K16: NASIK | L16: Mr. Arka Dey | M16: 50815918834 | N16: BLUE DART SARFACE | O16: WAG9/6k | P16: 70201134101308 | Q16: 62OP 30878 | R16: Short supply material dispatched now | S16: 21.36 | T16: INR | U16: =S16*F16 -> 1965.12
A17: 14 | B17: 109609637 | C17: 09670008476 | D17: M12 A TYPE FEMALE CONNECTER CRIMP CONTACT PIN PN 09670008476 | E17: Nos | F17: 57 | G17: UP/DC/FY22/00022 | H17: 44672 | I17: 44674 | J17: TEKNOCRATS CONTROL PVT. LTD. | K17: NASIK | L17: Mr. Arka Dey | M17: 50815918834 | N17: BLUE DART SARFACE | O17: WAG9/6k | P17: 70201134101308 | Q17: 62OP 30878 | R17: Short supply material dispatched now | S17: 18.62 | T17: INR | U17: =S17*F17 -> 1061.34
A18: 15 | B18: 111448661 | C18: 1802CP1043 | D18: Plug for Looming bar | E18: Nos | F18: 300 | G18: UP/DC/FY22/00022 | H18: 44672 | I18: 44674 | J18: TEKNOCRATS CONTROL PVT. LTD. | K18: NASIK | L18: Mr. Arka Dey | M18: 50815918834 | N18: BLUE DART SARFACE | O18: WAG9/6k | P18: 70201134101308 | Q18: 62OP 30878 | R18: Short supply material dispatched now | S18: 48.6 | T18: INR | U18: =S18*F18 -> 14580
A19: 16 | B19: 110317066 | C19: 110317066 | D19: SCREW STAR M4 X 15 V4D 9039 | E19: Nos | F19: 640 | G19: UP/DC/FY22/00022 | H19: 44672 | I19: 44674 | J19: TEKNOCRATS CONTROL PVT. LTD. | K19: NASIK | L19: Mr. Arka Dey | M19: 50815918834 | N19: BLUE DART SARFACE | O19: WAG9/6k | P19: 70201134101308 | Q19: 62OP 30878 | R19: Short supply material dispatched now | S19: 1.15 | T19: INR | U19: =S19*F19 -> 736
A20: 17 | B20: 111448667 | C20: 221 | D20: SIKAFLEX 221 | E20: Nos | F20: 48 | G20: UP/DC/FY22/00022 | H20: 44672 | I20: 44674 | J20: TEKNOCRATS CONTROL PVT. LTD | K20: NASIK | L20: Mr. Arka Dey | M20: 50815918834 | N20: BLUE DART SARFACE | O20: WAG9/6k | P20: 70201134101308 | Q20: 62OP 30878 | R20: Short supply material dispatched now | S20: 475.2 | T20: INR | U20: =S20*F20 -> 22809.6
A21: 18 | B21: 109710327 | C21: 280-621 | D21: Wago- 4 Conductor through treminal block 280-621 | E21: Nos | F21: 1100 | G21: UP/DC/FY22/00022 | H21: 44672 | I21: 44674 | J21: TEKNOCRATS CONTROL PVT. LTD. | K21: NASIK | L21: Mr. Arka Dey | M21: 50815918834 | N21: BLUE DART SARFACE | O21: WAG9/6k | P21: 70201134101308 | Q21: 62OP 30878 | R21: Short supply material dispatched now | S21: 25.31 | T21: INR | U21: =S21*F21 -> 27841
A22: 19 | B22: 109611234 | C22: 3742612236 | D22: Active Speed Sensors suitable for IGBT locos [3-Phase Locos] DSD 1616.73 QHW - F267S 3742612236 | E22: Nos | F22: 1 | G22: UP/DC/FY22/00024 | H22: 44672 | I22: 44674 | J22: Siemens Ltd- Nasik Work | K22: Nasik | L22: Mr. Arka Dey | M22: 50815918845 | N22: BLUE DART SARFACE | O22: WAG9/6k | P22: - | Q22: - | R22: For Lab Testing | S22: 19072.55 | T22: INR | U22: =S22*F22 -> 19072.55
A23: 20 | B23: 109447742 | C23: 803102 | D23: 803102 LION-DI16-72V-110V-LUE LION I/O MODULE DIGITAL OUTPUTS | E23: Nos | F23: 1 | G23: UP/DC/FY22/00035 | H23: 44682 | I23: 44682 | J23: DLW- DDU SHED MUGAL SARAI | K23: VARANASI | L23: Mr. Arka Dey | M23: BY HAND | N23: Mr. Saurabh Mishra | O23: 6000HP: CLW PO 6k49x | P23: 20212095100413 | Q23: 62OP-30878.P.89 | R23: Material for BLW Commissioning against 49x CLW | S23: 15118.36 | T23: INR | U23: =S23*F23 -> 15118.36
A24: 21 | B24: 109492180 | C24: 09670094701 | D24: D- SUB CRIMP 9-POLE FEMALE ASSEMBLY '09670094701 | E24: Nos | F24: 45 | G24: UP/DC/FY22/00037 | H24: 44683 | I24: 44683 | J24: Siemens / Guest house | K24: Paschim Burdwan WB | L24: Mr. Arka Dey | M24: BY HAND | N24: Mr. Saurabh Mishra | O24: 6000HP: CLW PO 6k49x | P24: 70201134101308 | Q24: 62OP 30878 | R24: Short material supply to CLW | S24: 32.22 | T24: INR | U24: =S24*F24 -> 1449.9
A25: 22 | B25: 109492212 | C25: 09670008576 | D25: D-Sub, MA AWG 20-24 crimp cont 09670008576 | E25: Nos | F25: 139 | G25: UP/DC/FY22/00037 | H25: 44683 | I25: 44683 | J25: Siemens / Guest house | K25: Paschim Burdwan WB | L25: Mr. Arka Dey | M25: BY HAND | N25: Mr. Saurabh Mishra | O25: 6000HP: CLW PO 6k49x | P25: 70201134101308 | Q25: 62OP 30878 | R25: Short material supply to CLW | S25: 11.26 | T25: INR | U25: =S25*F25 -> 1565.14
A26: 23 | B26: 109492212 | C26: 09670008576 | D26: D-Sub, MA AWG 20-24 crimp cont 09670008576 | E26: Nos | F26: 210 | G26: UP/DC/FY22/00037 | H26: 44683 | I26: 44683 | J26: Siemens / Guest house | K26: Paschim Burdwan WB | L26: Mr. Arka Dey | M26: BY HAND | N26: Mr. Saurabh Mishra | O26: 6000HP: CLW PO 6k49x | P26: 70201134101308 | Q26: 62OP 30878 | R26: Short material supply to CLW | S26: 11.26 | T26: INR | U26: =S26*F26 -> 2364.6
A27: 24 | B27: 109492198 | C27: 21038811405 | D27: M12 CRIMP SLIM DESIGN 4 POL D CODED M '21038811405 | E27: Nos | F27: 170 | G27: UP/DC/FY22/00037 | H27: 44683 | I27: 44683 | J27: Siemens / Guest house | K27: Paschim Burdwan WB | L27: Mr. Arka Dey | M27: BY HAND | N27: Mr. Saurabh Mishra | O27: 6000HP: CLW PO 6k49x | P27: 70201134101308 | Q27: 62OP 30878 | R27: Short material supply to CLW | S27: 1139.38 | T27: INR | U27: =S27*F27 -> 193694.6
A28: 25 | B28: 109609632 | C28: 09150043013 | D28: HAN 4 QUINTAX STIFT, 3-9.5MM 09150043013 | E28: Nos | F28: 12 | G28: UP/DC/FY22/00040 | H28: 44685 | I28: 44685 | J28: Siemens / Guest house | K28: Paschim Burdwan WB | L28: Mr. Arka Dey | M28: BY HAND | N28: Mr. Saurabh Mishra | O28: 6000HP: CLW PO 6k49x | P28: 70201134101308 | Q28: 62OP 30878 | R28: Short material supply to CLW | S28: 100.06 | T28: INR | U28: =S28*F28 -> 1200.72
A29: 26 | B29: 109492181 | C29: 09670003476 | D29: HARTING D SUB -S- FEMALE-18-22 CRIMP CONDUCT P.N. 09670003476 | E29: Nos | F29: 50 | G29: UP/DC/FY22/00040 | H29: 44685 | I29: 44685 | J29: Siemens / Guest house | K29: Paschim Burdwan WB | L29: Mr. Arka Dey | M29: BY HAND | N29: Mr. Saurabh Mishra | O29: 6000HP: CLW PO 6k49x | P29: 70201134101308 | Q29: 62OP 30878 | R29: Short material supply to CLW | S29: 18.35 | T29: INR | U29: =S29*F29 -> 917.5
A30: 27 | B30: 109609630 | C30: 09150006123 | D30: HARTING R15-STI-C (AU) 0.5-AWG20 09150006123 | E30: Nos | F30: 48 | G30: UP/DC/FY22/00040 | H30: 44685 | I30: 44685 | J30: Siemens / Guest house | K30: Paschim Burdwan WB | L30: Mr. Arka Dey | M30: BY HAND | N30: Mr. Saurabh Mishra | O30: 6000HP: CLW PO 6k49x | P30: 70201134101308 | Q30: 62OP 30878 | R30: Short material supply to CLW | S30: 19.26 | T30: INR | U30: =S30*F30 -> 924.48
A31: 28 | B31: 109612592 | C31: 280-941/281-492 | D31: WAGO COMPONENT TERMINAL BLOCK 280-941/281-492 | E31: Nos | F31: 7 | G31: UP/DC/FY22/00042 | H31: 44686 | I31: 44688 | J31: SIEMENS LTD MIBILITY | K31: GURGAON | L31: MR. Ashish Mishra | M31: 40761719364 | N31: BLUE DART | O31: WAG-9/9K UPGRADE | R31: For TKD 9K Loco upgrade | S31: 136.2 | T31: INR | U31: =S31*F31 -> 953.4
A32: 29 | B32: 107123964 | C32: FAHZ5-P3-024/028/007 | D32: SPEED SENSOR NORIS | E32: Nos | F32: 70 | G32: UP/DC/FY22/00046 | H32: 44690 | I32: 44694 | J32: Siemens ltd Jodhpur Site | K32: Bhagat Ki kothi Jodhpur | L32: Mr. Arka Dey | M32: 223951853 | N32: Spoton | O32: DE loco AMC | P32: - | Q32: 62OP-30781.P.02 | R32: Faulty Batch Replacement from Noris And Transport and Packaging cost to be Debits CS | S32: 12996 | T32: INR | U32: =S32*F32 -> 909720
A33: 30 | B33: 107182194 | C33: 107182194 | D33: MS Louvers for HLC | E33: Nos | F33: 8 | G33: UP/DC/FY22/00053 | H33: 44694 | I33: 44694 | J33: ELECTRIC LOCO SHED LALAGUDA | K33: SECUNDERABAD | L33: MR. Akash Goyal | M33: 223951852 | N33: Spoton | O33: HLC Project | P33: - | Q33: 62303002 | R33: This material free supply to customer for HLC Project | S33: 2850 | T33: INR | U33: =S33*F33 -> 22800
A34: 31 | C34: CAB-ETH-M12-M12-5M | D34: COMMUNICATION CABLE CAB-ETH-M12-M12-5M | E34: Nos | F34: 15 | G34: UP/DC/FY22/00054 | H34: 44694 | I34: 44694 | J34: Siemens / Guest house | K34: Paschim Burdwan WB | L34: Mr. Arka Dey | M34: 223951851 | N34: Spoton | O34: 6000HP: CLW PO 6k49x | P34: 70201134101308 | Q34: 62OP 30878 | R34: Short material supply to CLW | S34: 1000 | T34: INR | U34: =S34*F34 -> 15000
A35: 32 | C35: POWER SUPPLY CABLE FOR RAMMLOT DEVICE | D35: POWER SUPPLY CABLE FOR RAMMLOT DEVICE | E35: Nos | F35: 1 | G35: UP/DC/FY22/00054 | H35: 44694 | I35: 44694 | J35: Siemens / Guest house | K35: Paschim Burdwan WB | L35: Mr. Arka Dey | M35: 223951851 | N35: Spoton | O35: 6000HP: CLW PO 6k49x | P35: 70201134101308 | Q35: 62OP 30878 | R35: Short material supply to CLW | S35: 1000 | T35: INR | U35: =S35*F35 -> 1000
A36: 33 | B36: 107157518 | C36: 107157518 | D36: REMMLOT DEVICE | E36: Nos | F36: 1 | G36: UP/DC/FY22/00054 | H36: 44694 | I36: 44694 | J36: Siemens / Guest house | K36: Paschim Burdwan WB | L36: Mr. Arka Dey | M36: 223951851 | N36: Spoton | O36: 6000HP: CLW PO 6k49x | P36: 70201134101308 | Q36: 62OP 30878 | R36: Short material supply to CLW | S36: 160800 | T36: INR | U36: =S36*F36 -> 160800
A37: 34 | B37: 107157518 | C37: 107157518 | D37: REMMLOT DEVICE | E37: Nos | F37: 3 | G37: UP/DC/FY22/00054 | H37: 44694 | I37: 44694 | J37: Siemens / Guest house | K37: Paschim Burdwan WB | L37: Mr. Arka Dey | M37: 223951851 | N37: Spoton | O37: 6000HP: CLW PO 6k49x | P37: 70201134101308 | Q37: 62OP 30878 | R37: Short material supply to CLW | S37: 160800 | T37: INR | U37: =S37*F37 -> 482400
A38: 35 | C38: PMU 22 ABB | D38: CRASH WORTHY MEMORY MODULE PMU22ABB U-BETR- 5VDC SR NO 180084164 , 180084167 | E38: Nos | F38: 2 | G38: UP/DC/FY22/00057 | H38: 44700 | I38: 44700 | J38: Siemens Ltd. - RSLM | K38: Gurgaon | L38: Mr. Ashok Tripathy | M38: 215973540 | N38: Spoton/Delhivery | O38: - | P38: - | Q38: - | R38: This is a damage (Faulty) material | S38: 5000 | T38: INR | U38: =S38*F38 -> 10000
A39: 36 | B39: 109492197 | C39: 61030000067 | D39: CRIMP FLANGE FOR D-SUB HARTING (S102117360) FORMVB CONNECTOR 61030000067 | E39: Nos | F39: 40 | G39: UP/DC/FY22/00058 | H39: 44700 | I39: 44700 | J39: TEKNOCRATS CONTROL PVT. LTD. | K39: NASIK | L39: Mr. Tushar Narkhade | M39: 215973541 | N39: Spoton/Delhivery | O39: WAG9/6k | P39: 70201134101308 | Q39: 62OP 30878 | R39: Short supply material dispatched now | S39: 66.92 | T39: INR | U39: =S39*F39 -> 2676.8
A40: 37 | B40: 109492180 | C40: 09670094701 | D40: D- SUB CRIMP 9-POLE FEMALE ASSEMBLY '09670094701 | E40: Nos | F40: 70 | G40: UP/DC/FY22/00058 | H40: 44700 | I40: 44700 | J40: Technocrats' Control Systems (India) Pvt. Ltd. | K40: NASIK | L40: Mr. Tushar Narkhade | M40: 215973541 | N40: Spoton/Delhivery | O40: 6000HP: CLW PO 6k49x | P40: 70201134101308 | Q40: 62OP 30878 | R40: Short supply material dispatched now | S40: 32.22 | T40: INR | U40: =S40*F40 -> 2255.4
...

Sheet Summery
G1: =G2-'In-ward Register'!M2 -> -1157582.4 | H1: =H2-'Out-ward Register'!F2 -> 0 | J1: Value In Minr → | K1: =K2/1000000 -> 0.0948 | L1: =L2/1000000 -> 0 | M1: =M2/1000000 -> 0.0948 | N1: =L1+M1 -> 0.0948
B2: MIS As on 31-July -25 | G2: =SUBTOTAL(9,G4:G9660) -> 3 | H2: =SUM(H4:H1048576) -> 604899.94 | I2: =G2-H2 -> -604896.94 | K2: =SUBTOTAL(9,K4:K9660) -> 94800 | L2: =SUBTOTAL(9,L4:L9660) -> 0 | M2: =K2-L2 -> 94800 | R2: =M2-Q2 -> 94800
A3: Project | B3: Sr. No. | C3: SAP Code | D3: Part Code | E3: Description | F3: UOM | G3: Received Qty | H3: Dispatch Qty | I3: Balance Qty | J3: Avg. Price As per P.o. | K3: Received Qty Value | L3: Dispatched Qty Value | M3: Balance Qty Value | N3: Remark | O3: Value In % | P3: 1111a
A4: Project 6K | B4: 36 | C4: 109611234 | D4: 3742612236 | E4: ACTIVE SPEED SENSORS SUITABLE FOR IGBT LOCOS [3-PHASE LOCOS] DSD 1616.73 QHW - F267S 3742612236 | F4: Nos | G4: =SUMIF('In-ward Register'!$K:$K,Summery!$E:$E,'In-ward Register'!$M:$M) -> 3036 | H4: =SUMIF('Out-ward Register'!$D:$D,Summery!$E:$E,'Out-ward Register'!$F:$F) -> 2526 | I4: =G4-H4 -> 510 | J4: 26302 | K4: =J4*G4 -> 79852872 | L4: =J4*H4 -> 66438852 | M4: =K4-L4 -> 13414020 | O4: =M4/M$2*100 -> 14149.81
A5: Project 6K | B5: 998 | C5: 111393237 | D5: APTXA003C | E5: Driver Display Unit for 3- Phase Locomotive UIC keyboard, MVB | F5: Nos | G5: =SUMIF('In-ward Register'!$K:$K,Summery!$E:$E,'In-ward Register'!$M:$M) -> 324 | H5: =SUMIF('Out-ward Register'!$D:$D,Summery!$E:$E,'Out-ward Register'!$F:$F) -> 280 | I5: =G5-H5 -> 44 | J5: 178635.05 | K5: =J5*G5 -> 57877758 | L5: =J5*H5 -> 50017815 | M5: =K5-L5 -> 7859942.4
A6: Project-HLC | B6: 1165 | C6: 105401095 | D6: SA2V00001200316 | E6: SIBCOS M2500-2-0 | F6: Nos | G6: =SUMIF('In-ward Register'!$K:$K,Summery!$E:$E,'In-ward Register'!$M:$M) -> 31 | H6: =SUMIF('Out-ward Register'!$D:$D,Summery!$E:$E,'Out-ward Register'!$F:$F) -> 7 | I6: =G6-H6 -> 24 | J6: 201000 | K6: =J6*G6 -> 6231000 | L6: =J6*H6 -> 1407000 | M6: =K6-L6 -> 4824000
A7: Project 6K | B7: 934 | C7: 109447744 | D7: 803203 | E7: 803203 LION-DO8-24V-110V-LUE LION I/O MODULE DIGITAL OUTPUTS | F7: Nos | G7: =SUMIF('In-ward Register'!$K:$K,Summery!$E:$E,'In-ward Register'!$M:$M) -> 726 | H7: =SUMIF('Out-ward Register'!$D:$D,Summery!$E:$E,'Out-ward Register'!$F:$F) -> 530 | I7: =G7-H7 -> 196 | J7: 20246.37 | K7: =J7*G7 -> 14698865 | L7: =J7*H7 -> 10730576 | M7: =K7-L7 -> 3968288.5 | O7: =M7/M$2*100 -> 4185.9584
A8: Project 6K | B8: 355 | C8: 107157518/ 112171911 | D8: LT30 | E8: REMMLOT DEVICE | F8: Nos | G8: =SUMIF('In-ward Register'!$K:$K,Summery!$E:$E,'In-ward Register'!$M:$M) -> 351 | H8: =SUMIF('Out-ward Register'!$D:$D,Summery!$E:$E,'Out-ward Register'!$F:$F) -> 326 | I8: =G8-H8 -> 25 | J8: 158554.7 | K8: =J8*G8 -> 55652700 | L8: =J8*H8 -> 51688832 | M8: =K8-L8 -> 3963867.5 | O8: =M8/M$2*100 -> 4181.2948
A9: Project 6K | B9: 598 | C9: 109492176 | D9: 45953050 | E9: MVB CABLE BL-02 X S (ST) CHX 2 X 2 X 0.5 MM DBN 459530 | F9: Mtr. | G9: =SUMIF('In-ward Register'!$K:$K,Summery!$E:$E,'In-ward Register'!$M:$M) -> 48241 | H9: =SUMIF('Out-ward Register'!$D:$D,Summery!$E:$E,'Out-ward Register'!$F:$F) -> 38348.5 | I9: =G9-H9 -> 9892.5 | J9: 293.43 | K9: =J9*G9 -> 14155357 | L9: =J9*H9 -> 11252600 | M9: =K9-L9 -> 2902756.3 | O9: =M9/M$2*100 -> 3061.9792
A10: Project-HLC | B10: 1151 | C10: A5E38077362 | D10: SA5E35109084 | E10: A2V00001450989 HLC 4QS SPAR | F10: Nos | G10: =SUMIF('In-ward Register'!$K:$K,Summery!$E:$E,'In-ward Register'!$M:$M) -> 13 | H10: =SUMIF('Out-ward Register'!$D:$D,Summery!$E:$E,'Out-ward Register'!$F:$F) -> 10 | I10: =G10-H10 -> 3 | J10: 950000 | K10: =J10*G10 -> 12350000 | L10: =J10*H10 -> 9500000 | M10: =K10-L10 -> 2850000
A11: Project 6K | B11: 880 | C11: 112169820 | D11: ERLBT157013XXX2 | E11: CABLE 1C X 2.5 SQ MM - 4 GKW - 1.8/3 KV | F11: Mtr. | G11: =SUMIF('In-ward Register'!$K:$K,Summery!$E:$E,'In-ward Register'!$M:$M) -> 118746 | H11: =SUMIF('Out-ward Register'!$D:$D,Summery!$E:$E,'Out-ward Register'!$F:$F) -> 40457 | I11: =G11-H11 -> 78289 | J11: 34.6 | K11: =J11*G11 -> 4108611.6 | L11: =J11*H11 -> 1399812.2 | M11: =K11-L11 -> 2708799.4 | O11: =M11/M$2*100 -> 2857.3833
A12: Project 6K | B12: 10 | C12: 101999218 | D12: XL KF i (A2B00075622) | E12: A2B00075622 DRIVER'S DESK TERMINAL SITET XL KF 1 74V | F12: Nos | G12: =SUMIF('In-ward Register'!$K:$K,Summery!$E:$E,'In-ward Register'!$M:$M) -> 111 | H12: =SUMIF('Out-ward Register'!$D:$D,Summery!$E:$E,'Out-ward Register'!$F:$F) -> 101 | I12: =G12-H12 -> 10 | J12: 233573.6 | K12: =J12*G12 -> 25926670 | L12: =J12*H12 -> 23590934 | M12: =K12-L12 -> 2335736 | O12: =M12/M$2*100 -> 2463.8565
A13: Project 9K | B13: 741 | C13: 112137134 | D13: 21038811406 | E13: M12 CRIMP SLIM DESIGN 4 POL D CODED M '21038811406 | F13: Nos | G13: =SUMIF('In-ward Register'!$K:$K,Summery!$E:$E,'In-ward Register'!$M:$M) -> 8913 | H13: =SUMIF('Out-ward Register'!$D:$D,Summery!$E:$E,'Out-ward Register'!$F:$F) -> 6493 | I13: =G13-H13 -> 2420 | J13: 930.97 | K13: =J13*G13 -> 8297735.6 | L13: =J13*H13 -> 6044788.2 | M13: =K13-L13 -> 2252947.4 | O13: =M13/M$2*100 -> 2376.5268
A14: Project 6K | B14: 551 | C14: 110408288 | D14: 3062607559 | E14: PULSE WHEEL FTP 521/120 | F14: Nos | G14: =SUMIF('In-ward Register'!$K:$K,Summery!$E:$E,'In-ward Register'!$M:$M) -> 3244 | H14: =SUMIF('Out-ward Register'!$D:$D,Summery!$E:$E,'Out-ward Register'!$F:$F) -> 2484 | I14: =G14-H14 -> 760 | J14: 2750 | K14: =J14*G14 -> 8921000 | L14: =J14*H14 -> 6831000 | M14: =K14-L14 -> 2090000 | O14: =M14/M$2*100 -> 2204.6414
A15: Project 6K | B15: 679 | C15: 109492179 | D15: 12568935 | E15: ETHERNET CABLE RAILCAT CAT 5E 4 X 22AWG XMS RADOX TRACTION CABLE | F15: Mtr. | G15: =SUMIF('In-ward Register'!$K:$K,Summery!$E:$E,'In-ward Register'!$M:$M) -> 84701 | H15: =SUMIF('Out-ward Register'!$D:$D,Summery!$E:$E,'Out-ward Register'!$F:$F) -> 60702 | I15: =G15-H15 -> 23999 | J15: 82.11 | K15: =J15*G15 -> 6954799.1 | L15: =J15*H15 -> 4984241.2 | M15: =K15-L15 -> 1970557.9 | O15: =M15/M$2*100 -> 2078.6476
A16: Project-HLC | B16: 938 | C16: 111367611 | D16: 111367611 | E16: IV Coupler Socket with 1m cable ( Complete Set) | F16: Nos | G16: =SUMIF('In-ward Register'!$K:$K,Summery!$E:$E,'In-ward Register'!$M:$M) -> 66 | H16: =SUMIF('Out-ward Register'!$D:$D,Summery!$E:$E,'Out-ward Register'!$F:$F) -> 6 | I16: =G16-H16 -> 60 | J16: 32750 | K16: =J16*G16 -> 2161500 | L16: =J16*H16 -> 196500 | M16: =K16-L16 -> 1965000
A17: Project 6K | B17: 154 | C17: 111400055 | D17: MS3474W14-5P-SQSC 01268739 | E17: AMPHENOL PART NO:- MS3474W14-5P-SQSC 01268739 | F17: Nos | G17: =SUMIF('In-ward Register'!$K:$K,Summery!$E:$E,'In-ward Register'!$M:$M) -> 3780 | H17: =SUMIF('Out-ward Register'!$D:$D,Summery!$E:$E,'Out-ward Register'!$F:$F) -> 2659 | I17: =G17-H17 -> 1121 | J17: 1732 | K17: =J17*G17 -> 6546960 | L17: =J17*H17 -> 4605388 | M17: =K17-L17 -> 1941572 | O17: =M17/M$2*100 -> 2048.0717
A18: Project 6K | B18: 721 | C18: A5E49966102 | D18: A5E49966102A, Rev02 | E18: Cu bushing flag busbar 2 A5E49966102A, Rev02 | F18: Nos | G18: =SUMIF('In-ward Register'!$K:$K,Summery!$E:$E,'In-ward Register'!$M:$M) -> 4843 | H18: =SUMIF('Out-ward Register'!$D:$D,Summery!$E:$E,'Out-ward Register'!$F:$F) -> 3339 | I18: =G18-H18 -> 1504 | J18: 1241.95 | K18: =J18*G18 -> 6014763.9 | L18: =J18*H18 -> 4146871.1 | M18: =K18-L18 -> 1867892.8 | O18: =M18/M$2*100 -> 1970.3511
A19: Project 6K | B19: 620 | C19: 110710681 | D19: 3EHP430699R0001 | E19: Braided Busbars Item1 WAG9-6K-EN3-TES-01 | F19: Nos | G19: =SUMIF('In-ward Register'!$K:$K,Summery!$E:$E,'In-ward Register'!$M:$M) -> 4138 | H19: =SUMIF('Out-ward Register'!$D:$D,Summery!$E:$E,'Out-ward Register'!$F:$F) -> 3322 | I19: =G19-H19 -> 816 | J19: 2153 | K19: =J19*G19 -> 8909114 | L19: =J19*H19 -> 7152266 | M19: =K19-L19 -> 1756848 | O19: =M19/M$2*100 -> 1853.2152
A20: Project-HLC | B20: 1164 | C20: A5E39006935 | D20: A2V00001202513 | E20: Trigger Unit | F20: Nos | G20: =SUMIF('In-ward Register'!$K:$K,Summery!$E:$E,'In-ward Register'!$M:$M) -> 35 | H20: =SUMIF('Out-ward Register'!$D:$D,Summery!$E:$E,'Out-ward Register'!$F:$F) -> 9 | I20: =G20-H20 -> 26 | J20: 67185 | K20: =J20*G20 -> 2351475 | L20: =J20*H20 -> 604665 | M20: =K20-L20 -> 1746810
A21: WAP-7 Locomotive | B21: 699 | C21: 108221269 | D21: WAP-7 Locomotive | E21: FABRICATED BOGIE FRAME COMPLETE FOR WAG-9HC LOCOMOTIVE / FABRICATED BOGIE FRAME COMPLETE FOR WAP-7 LOCOMOTIVE | F21: Nos | G21: =SUMIF('In-ward Register'!$K:$K,Summery!$E:$E,'In-ward Register'!$M:$M) -> 2 | H21: =SUMIF('Out-ward Register'!$D:$D,Summery!$E:$E,'Out-ward Register'!$F:$F) -> 0 | I21: =G21-H21 -> 2 | J21: 873333 | K21: =J21*G21 -> 1746666 | L21: =J21*H21 -> 0 | M21: =K21-L21 -> 1746666 | O21: =M21/M$2*100 -> 1842.4747
A22: Project-HLC | B22: 1006 | C22: 105401093 | D22: SA2V00001680232 | E22: FAN 3PHASE 415V 3KW 1PP SA2V00001680232 | F22: Nos | G22: =SUMIF('In-ward Register'!$K:$K,Summery!$E:$E,'In-ward Register'!$M:$M) -> 15 | H22: =SUMIF('Out-ward Register'!$D:$D,Summery!$E:$E,'Out-ward Register'!$F:$F) -> 2 | I22: =G22-H22 -> 13 | J22: 133000 | K22: =J22*G22 -> 1995000 | L22: =J22*H22 -> 266000 | M22: =K22-L22 -> 1729000
A23: Project 6K | B23: 692 | C23: 110710682 | D23: Item2 WAG9-6K-EN3-TES-01 | E23: Braided Busbars Item2 WAG9-6K-EN3-TES-01 | F23: Nos | G23: =SUMIF('In-ward Register'!$K:$K,Summery!$E:$E,'In-ward Register'!$M:$M) -> 4126 | H23: =SUMIF('Out-ward Register'!$D:$D,Summery!$E:$E,'Out-ward Register'!$F:$F) -> 3310 | I23: =G23-H23 -> 816 | J23: 2078 | K23: =J23*G23 -> 8573828 | L23: =J23*H23 -> 6878180 | M23: =K23-L23 -> 1695648 | O23: =M23/M$2*100 -> 1788.6582
A24: other | B24: 534 | C24: 109447742 | D24: 803102 | E24: 803102 LION-DI16-72V-110V-LUE LION I/O MODULE DIGITAL OUTPUTS | F24: Nos | G24: =SUMIF('In-ward Register'!$K:$K,Summery!$E:$E,'In-ward Register'!$M:$M) -> 357 | H24: =SUMIF('Out-ward Register'!$D:$D,Summery!$E:$E,'Out-ward Register'!$F:$F) -> 253 | I24: =G24-H24 -> 104 | J24: 15118.36 | K24: =J24*G24 -> 5397254.5 | L24: =J24*H24 -> 3824945.1 | M24: =K24-L24 -> 1572309.4 | O24: =M24/M$2*100 -> 1658.5543
A25: Project-HLC | B25: 544 | C25: 112129061 | D25: S112129084 | E25: S112129084 SOCKET HOUSING ASSEMBLY | F25: Nos | G25: =SUMIF('In-ward Register'!$K:$K,Summery!$E:$E,'In-ward Register'!$M:$M) -> 182 | H25: =SUMIF('Out-ward Register'!$D:$D,Summery!$E:$E,'Out-ward Register'!$F:$F) -> 65 | I25: =G25-H25 -> 117 | J25: 13332 | K25: =J25*G25 -> 2426424 | L25: =J25*H25 -> 866580 | M25: =K25-L25 -> 1559844 | O25: =M25/M$2*100 -> 1645.4051
A26: other | B26: 683 | C26: 109674086 | D26: 5182-78083-01 | E26: HOTEL LOAD FILTER CAPACITOR FOR ELECTRIC LOCOMOTIVE WAP7 UPGRADE 750V / 50HZ / 0.6MF " SPEC NO - A6Z00044012347 REV-A "VISHAY PART NO- ACMKP 1.061/600 µF" | F26: Nos | G26: =SUMIF('In-ward Register'!$K:$K,Summery!$E:$E,'In-ward Register'!$M:$M) -> 30 | H26: =SUMIF('Out-ward Register'!$D:$D,Summery!$E:$E,'Out-ward Register'!$F:$F) -> 0 | I26: =G26-H26 -> 30 | J26: 51400 | K26: =J26*G26 -> 1542000 | L26: =J26*H26 -> 0 | M26: =K26-L26 -> 1542000 | O26: =M26/M$2*100 -> 1626.5823
A27: Project 6K | B27: 1161 | C27: A5E46683174 | D27: SA5E51759588 | E27: SIBCOS-MB_M1305-20-0 | F27: Nos | G27: =SUMIF('In-ward Register'!$K:$K,Summery!$E:$E,'In-ward Register'!$M:$M) -> 8 | H27: =SUMIF('Out-ward Register'!$D:$D,Summery!$E:$E,'Out-ward Register'!$F:$F) -> 0 | I27: =G27-H27 -> 8 | J27: 180000 | K27: =J27*G27 -> 1440000 | L27: =J27*H27 -> 0 | M27: =K27-L27 -> 1440000
A28: Project 6K | B28: 753 | C28: A5E49965045 | D28: A5E49965045 | E28: CU BUSHING FLAG BUSBAR 1 | F28: Nos | G28: =SUMIF('In-ward Register'!$K:$K,Summery!$E:$E,'In-ward Register'!$M:$M) -> 2368 | H28: =SUMIF('Out-ward Register'!$D:$D,Summery!$E:$E,'Out-ward Register'!$F:$F) -> 1616 | I28: =G28-H28 -> 752 | J28: 1798.2 | K28: =J28*G28 -> 4258137.6 | L28: =J28*H28 -> 2905891.2 | M28: =K28-L28 -> 1352246.4 | O28: =M28/M$2*100 -> 1426.4203
A29: Project 6K | B29: 933 | C29: 112148136 | D29: XS1-1113 | E29: 911113 Kaliber-XS1-1113 ( Storage Device) | F29: Nos | G29: =SUMIF('In-ward Register'!$K:$K,Summery!$E:$E,'In-ward Register'!$M:$M) -> 519 | H29: =SUMIF('Out-ward Register'!$D:$D,Summery!$E:$E,'Out-ward Register'!$F:$F) -> 438 | I29: =G29-H29 -> 81 | J29: 16356.12 | K29: =J29*G29 -> 8488826.3 | L29: =J29*H29 -> 7163980.6 | M29: =K29-L29 -> 1324845.7 | O29: =M29/M$2*100 -> 1397.5166
A30: Project 9K | B30: 782 | C30: 108221257 | D30: 590400005 | E30: SPHERIBLOC FOR AXLE GUIDE ROD/TM SUPPORT ARM FOR WAG9/WAP7 LOCO AS PER RDSO SPEC NO. RDSO/2007/EL/SPEC/0051 (REV.3) | F30: Nos | G30: =SUMIF('In-ward Register'!$K:$K,Summery!$E:$E,'In-ward Register'!$M:$M) -> 418 | H30: =SUMIF('Out-ward Register'!$D:$D,Summery!$E:$E,'Out-ward Register'!$F:$F) -> 266 | I30: =G30-H30 -> 152 | J30: 7400 | K30: =J30*G30 -> 3093200 | L30: =J30*H30 -> 1968400 | M30: =K30-L30 -> 1124800 | O30: =M30/M$2*100 -> 1186.4979
